<?xml version='1.0' encoding='utf-8'?>


<material name="black">
    <color rgba="0. 0. 0. 1" />
</material>
<material name="dark_grey">
    <color rgba="0.1 0.1 0.1 1" />
</material>
<material name="grey">
    <color rgba="0.6 0.6 0.6 1" />
</material>
<material name="white">
    <color rgba="0.9 0.9 0.9 1" />
</material>

<robot xmlns:xacro="http://www.ros.org/wiki/xacro" name="optimo">

    <link name="base_link">
        <visual>
            <origin xyz="0 0 1.0408340855860842566e-17" rpy="0 -0 0" />
            <geometry>
                <mesh filename="package://optimo_description/meshes/base_l.stl"/>
            </geometry>
            <material name="${white}"/>
        </visual>
        <collision>
            <origin xyz="0 0 1.0408340855860842566e-17" rpy="0 -0 0" />
            <geometry>
                <mesh filename="package://optimo_description/meshes/base_l.stl"/>
            </geometry>
        </collision>
        
    <visual>
    <origin xyz="0 0 0" rpy="0 -0 0" />
    <geometry>
    <mesh filename="package://optimo_description/meshes/base_r.stl"/>
    </geometry>
    <material name="base_r_material">
    <color rgba="1 1 1 1.0"/>
    </material>
    </visual>
    <collision>
    <origin xyz="0 0 0" rpy="0 -0 0" />
    <geometry>
    <mesh filename="package://optimo_description/meshes/base_r.stl"/>
    </geometry>
    </collision>
    <visual>
    <origin xyz="0 0 0" rpy="0 -0 0" />
    <geometry>
    <mesh filename="package://optimo_description/meshes/baseplate.stl"/>
    </geometry>
    <material name="baseplate_material">
    <color rgba="0.86666666666666669627 0.90980392156862743835 1 1.0"/>
    </material>
    </visual>
    <collision>
    <origin xyz="0 0 0" rpy="0 -0 0" />
    <geometry>
    <mesh filename="package://optimo_description/meshes/baseplate.stl"/>
    </geometry>
    </collision>
    <inertial>
    <origin xyz="0 0 0" rpy="0 0 0"/>
    <mass value="0" />
    <inertia ixx="0" ixy="0"  ixz="0" iyy="0" iyz="0" izz="0" />
    </inertial>
    </link>

    <link name="link1">
    <visual>
    <origin xyz="0 0 0.13075000225727398395" rpy="3.141592653589793116 -0 0" />
    <geometry>
    <mesh filename="package://optimo_description/meshes/link1.stl"/>
    </geometry>
    <material name="link1_material">
    <color rgba="1 1 1 1.0"/>
    </material>
    </visual>
    <collision>
    <origin xyz="0 0 0.13075000225727398395" rpy="3.141592653589793116 -0 0" />
    <geometry>
    <mesh filename="package://optimo_description/meshes/link1.stl"/>
    </geometry>
    </collision>
    <inertial>
    <origin xyz="0 0 0" rpy="0 0 0"/>
    <mass value="0" />
    <inertia ixx="0" ixy="0"  ixz="0" iyy="0" iyz="0" izz="0" />
    </inertial>
    </link>

    <link name="link2_a">
    <visual>
    <origin xyz="0 0.27000000000000001776 0.036750000000000039579" rpy="1.570796326794896558 1.570796326794896558 0" />
    <geometry>
    <mesh filename="package://optimo_description/meshes/link2_a.stl"/>
    </geometry>
    <material name="link2_a_material">
    <color rgba="1 1 1 1.0"/>
    </material>
    </visual>
    <collision>
    <origin xyz="0 0.27000000000000001776 0.036750000000000039579" rpy="1.570796326794896558 1.570796326794896558 0" />
    <geometry>
    <mesh filename="package://optimo_description/meshes/link2_a.stl"/>
    </geometry>
    </collision>
    <inertial>
    <origin xyz="0 0 0" rpy="0 0 0"/>
    <mass value="0" />
    <inertia ixx="0" ixy="0"  ixz="0" iyy="0" iyz="0" izz="0" />
    </inertial>
    </link>

    <link name="link2_b">
    <visual>
    <origin xyz="8.9969578614940243723e-14 0.34300000000000002709 0.041250000000000001943" rpy="1.570796326794896558 1.5707963267926474682 0" />
    <geometry>
    <mesh filename="package://optimo_description/meshes/link2_b.stl"/>
    </geometry>
    <material name="link2_b_material">
    <color rgba="1 1 1 1.0"/>
    </material>
    </visual>
    <collision>
    <origin xyz="8.9969578614940243723e-14 0.34300000000000002709 0.041250000000000001943" rpy="1.570796326794896558 1.5707963267926474682 0" />
    <geometry>
    <mesh filename="package://optimo_description/meshes/link2_b.stl"/>
    </geometry>
    </collision>
    <inertial>
    <origin xyz="0 0 0" rpy="0 0 0"/>
    <mass value="0" />
    <inertia ixx="0" ixy="0"  ixz="0" iyy="0" iyz="0" izz="0" />
    </inertial>
    </link>

    <link name="link3">
    <visual>
    <origin xyz="0 0 0.4377499953903249974" rpy="3.141592653589793116 -0 0" />
    <geometry>
    <mesh filename="package://optimo_description/meshes/link3.stl"/>
    </geometry>
    <material name="link3_material">
    <color rgba="1 1 1 1.0"/>
    </material>
    </visual>
    <collision>
    <origin xyz="0 0 0.4377499953903249974" rpy="3.141592653589793116 -0 0" />
    <geometry>
    <mesh filename="package://optimo_description/meshes/link3.stl"/>
    </geometry>
    </collision>
    <inertial>
    <origin xyz="0 0 0" rpy="0 0 0"/>
    <mass value="0" />
    <inertia ixx="0" ixy="0"  ixz="0" iyy="0" iyz="0" izz="0" />
    </inertial>
    </link>

    <link name="link4">
    <visual>
    <origin xyz="0 -0.67000000000000003997 0.033000000000000001554" rpy="-1.570796326794896558 -1.570796326794896558 0" />
    <geometry>
    <mesh filename="package://optimo_description/meshes/link4.stl"/>
    </geometry>
    <material name="link4_material">
    <color rgba="1 1 1 1.0"/>
    </material>
    </visual>
    <collision>
    <origin xyz="0 -0.67000000000000003997 0.033000000000000001554" rpy="-1.570796326794896558 -1.570796326794896558 0" />
    <geometry>
    <mesh filename="package://optimo_description/meshes/link4.stl"/>
    </geometry>
    </collision>
    <inertial>
    <origin xyz="0 0 0" rpy="0 0 0"/>
    <mass value="0" />
    <inertia ixx="0" ixy="0"  ixz="0" iyy="0" iyz="0" izz="0" />
    </inertial>
    </link>

    <link name="link5">
    <visual>
    <origin xyz="0 0 0.86275000000000001688" rpy="3.141592653589793116 -0 0" />
    <geometry>
    <mesh filename="package://optimo_description/meshes/link5.stl"/>
    </geometry>
    <material name="link5_material">
    <color rgba="1 1 1 1.0"/>
    </material>
    </visual>
    <collision>
    <origin xyz="0 0 0.86275000000000001688" rpy="3.141592653589793116 -0 0" />
    <geometry>
    <mesh filename="package://optimo_description/meshes/link5.stl"/>
    </geometry>
    </collision>
    <inertial>
    <origin xyz="0 0 0" rpy="0 0 0"/>
    <mass value="0" />
    <inertia ixx="0" ixy="0"  ixz="0" iyy="0" iyz="0" izz="0" />
    </inertial>
    </link>

    <link name="link6">
    <visual>
    <origin xyz="0 1.0700000000000000622 -0.031350000000001002065" rpy="1.570796326794896558 1.570796326794896558 0" />
    <geometry>
    <mesh filename="package://optimo_description/meshes/link6.stl"/>
    </geometry>
    <material name="link6_material">
    <color rgba="1 1 1 1.0"/>
    </material>
    </visual>
    <collision>
    <origin xyz="0 1.0700000000000000622 -0.031350000000001002065" rpy="1.570796326794896558 1.570796326794896558 0" />
    <geometry>
    <mesh filename="package://optimo_description/meshes/link6.stl"/>
    </geometry>
    </collision>
    <inertial>
    <origin xyz="0 0 0" rpy="0 0 0"/>
    <mass value="0" />
    <inertia ixx="0" ixy="0"  ixz="0" iyy="0" iyz="0" izz="0" />
    </inertial>
    </link>

    <link name="link7">
    <visual>
    <origin xyz="0 0 1.1492500000000001048" rpy="-3.141592653589793116 -3.3743814299046044802e-20 -9.709125554995493097e-53" />
    <geometry>
    <mesh filename="package://optimo_description/meshes/link7.stl"/>
    </geometry>
    <material name="link7_material">
    <color rgba="1 1 1 1.0"/>
    </material>
    </visual>
    <collision>
    <origin xyz="0 0 1.1492500000000001048" rpy="-3.141592653589793116 -3.3743814299046044802e-20 -9.709125554995493097e-53" />
    <geometry>
    <mesh filename="package://optimo_description/meshes/link7.stl"/>
    </geometry>
    </collision>
    <inertial>
    <origin xyz="0 0 0" rpy="0 0 0"/>
    <mass value="0" />
    <inertia ixx="0" ixy="0"  ixz="0" iyy="0" iyz="0" izz="0" />
    </inertial>
    </link>

    <joint name="joint6" type="continuous">
    <origin xyz="0 -0.079749999999999987566 -0.031350000000009294043" rpy="-1.570796326794896558 1.5707963267948894526 0" />
    <parent link="link6" />
    <child link="link7" />
    <axis xyz="0 0 1"/>
    </joint>

    <joint name="joint5" type="continuous">
    <origin xyz="-0.030835783890162483944 0 -0.20734806212796685898" rpy="1.5704817801586226089 1.9259401494261785314e-34 -1.570796326794896558" />
    <parent link="link5" />
    <child link="link6" />
    <axis xyz="0 0 1"/>
    </joint>

    <joint name="joint4" type="continuous">
    <origin xyz="0 0.19274999999999997691 0.033000000000000001554" rpy="1.570796326794896558 -1.570796326794896558 0" />
    <parent link="link4" />
    <child link="link5" />
    <axis xyz="0 0 1"/>
    </joint>

    <joint name="joint3" type="continuous">
    <origin xyz="-0.032750000000000001332 0 -0.23225000460967509808" rpy="-1.570796326794896558 -0 -1.570796326794896558" />
    <parent link="link3" />
    <child link="link4" />
    <axis xyz="0 0 1"/>
    </joint>

    <joint name="joint2" type="continuous">
    <origin xyz="8.9969578614940243723e-14 -0.0917500197164549669 0.041250000000000001943" rpy="-1.570796326794896558 1.570796326794896558 0" />
    <parent link="link2_b" />
    <child link="link3" />
    <axis xyz="0 0 1"/>
    </joint>

    <joint name="dummy" type="fixed">
        <origin xyz="0 -0.073000000000000009326 -0.0045000001250000559727" rpy="1.4180814337892998162e-16 -0 0" />
        <parent link="link2_a" />
        <child link="link2_b" />
    </joint>

    <joint name="joint1" type="continuous">
    <origin xyz="0.037750213382365192805 0 -0.13924999774272603381" rpy="1.570796326794896558 -0 -1.570796326794896558" />
    <parent link="link1" />
    <child link="link2_a" />
    <axis xyz="0 0 1"/>
    </joint>

    <joint name="joint0" type="continuous">
        <origin xyz="0 0 0.13075000000000000511" rpy="3.141592653589793116 -0 0" />
        <parent link="base_link" />
        <child link="link1" />
        <axis xyz="0 0 1"/>
        <!-- <limit lower="-2.967" upper="2.967" effort="0" velocity="3.35103"/> -->
    </joint>


</robot>
