<?xml version="1.0" ?>
<!-- =================================================================================== -->
<!-- |    This document was autogenerated by xacro from plato_manipulator.urdf.xacro   | -->
<!-- |    EDITING THIS FILE BY HAND IS NOT RECOMMENDED                                 | -->
<!-- =================================================================================== -->
<robot name="plato">
  <link name="optimo_base_link">
    </link>
  <joint name="optimo_base_joint" type="fixed">
    <parent link="optimo_base_link"/>
    <child link="optimo_link0"/>
    <origin rpy="0 0 0" xyz="0 0 0.27"/>
  </joint>
  <!-- Robot Links -->
  <link name="optimo_link0">
    <visual>
      <geometry>
        <mesh filename="file:///home/dk/workspaces/plato_ws/install/optimo_description/share/optimo_description/meshes/link0.stl"/>
      </geometry>
      <material name="LightGrey">
        <color rgba="0.999 0.999 0.999 1.0"/>
      </material>
    </visual>
    <collision>
      <geometry>
        <mesh filename="file:///home/dk/workspaces/plato_ws/install/optimo_description/share/optimo_description/meshes/col0.stl"/>
      </geometry>
    </collision>
    <inertial>
      <!-- Doesn't matter, just placeholder values -->
      <origin xyz="0 0 0"/>
      <mass value="1"/>
      <inertia ixx="0" ixy="0.0" ixz="0.0" iyy="0" iyz="0.0" izz="0"/>
    </inertial>
  </link>
  <link name="optimo_link1">
    <visual>
      <geometry>
        <sphere radius="0.01"/>
      </geometry>
      <material name="LightGrey">
        <color rgba="0.999 0.999 0.999 1.0"/>
      </material>
    </visual>
  </link>
  <link name="optimo_link1_passive">
    <visual>
      <geometry>
        <mesh filename="file:///home/dk/workspaces/plato_ws/install/optimo_description/share/optimo_description/meshes/link1.stl"/>
      </geometry>
      <material name="LightGrey">
        <color rgba="0.999 0.999 0.999 1.0"/>
      </material>
    </visual>
    <collision>
      <geometry>
        <mesh filename="file:///home/dk/workspaces/plato_ws/install/optimo_description/share/optimo_description/meshes/col1.stl"/>
      </geometry>
    </collision>
    <inertial>
      <origin xyz="0 -0.01635 0.01549"/>
      <mass value="4.152"/>
      <inertia ixx="0.01" ixy="0.000017" ixz="-.00001" iyy="0.007494" iyz="0.0000213" izz="0.009939"/>
      <!-- <inertia ixx="0" ixy="0.0" ixz="0.0" iyy="0" iyz="0.0" izz="0"/> -->
    </inertial>
  </link>
  <link name="optimo_link2"/>
  <link name="optimo_link2_passive">
    <visual>
      <geometry>
        <mesh filename="file:///home/dk/workspaces/plato_ws/install/optimo_description/share/optimo_description/meshes/link2.stl"/>
      </geometry>
      <material name="LightGrey">
        <color rgba="0.999 0.999 0.999 1.0"/>
      </material>
    </visual>
    <collision>
      <geometry>
        <mesh filename="file:///home/dk/workspaces/plato_ws/install/optimo_description/share/optimo_description/meshes/col2.stl"/>
      </geometry>
    </collision>
    <inertial>
      <origin rpy="0 0 3.1415926518" xyz="0 -0.05063 0.05677"/>
      <mass value="1.72"/>
      <inertia ixx="0.005694" ixy="0" ixz="0" iyy="0.005902" iyz="-0.001353" izz="0.002415"/>
      <!-- <inertia ixx="0" ixy="0.0" ixz="0.0" iyy="0" iyz="0.0" izz="0"/> -->
    </inertial>
  </link>
  <link name="optimo_link3"/>
  <link name="optimo_link3_passive">
    <visual>
      <geometry>
        <mesh filename="file:///home/dk/workspaces/plato_ws/install/optimo_description/share/optimo_description/meshes/link3.stl"/>
      </geometry>
      <material name="LightGrey">
        <color rgba="0.999 0.999 0.999 1.0"/>
      </material>
    </visual>
    <collision>
      <geometry>
        <mesh filename="file:///home/dk/workspaces/plato_ws/install/optimo_description/share/optimo_description/meshes/col3.stl"/>
      </geometry>
    </collision>
    <inertial>
      <!-- Inertia values taken from yaml, but these seem like they cannot be accurate...-->
      <origin xyz="-0.000039 .098 0"/>
      <mass value="4.310"/>
      <inertia ixx="0.012989" ixy="-0.000015" ixz="-.000003" iyy="0.002584" iyz="0.000632" izz="0.01305"/>
      <!-- <inertia ixx="0" ixy="0.0" ixz="0.0" iyy="0" iyz="0.0" izz="0"/> -->
    </inertial>
  </link>
  <link name="optimo_link4"/>
  <link name="optimo_link4_passive">
    <origin rpy="0 0 0" xyz="0 0 0"/>
    <visual>
      <geometry>
        <mesh filename="file:///home/dk/workspaces/plato_ws/install/optimo_description/share/optimo_description/meshes/link4.stl"/>
      </geometry>
      <material name="LightGrey">
        <color rgba="0.999 0.999 0.999 1.0"/>
      </material>
    </visual>
    <collision>
      <geometry>
        <mesh filename="file:///home/dk/workspaces/plato_ws/install/optimo_description/share/optimo_description/meshes/col4.stl"/>
      </geometry>
    </collision>
    <inertial>
      <origin rpy="0 0 0" xyz="-.00001 0.048852 0.0688"/>
      <mass value="1.09"/>
      <inertia ixx="0.007" ixy="-3.989e-7" ixz="0.002" iyy="0.007" iyz="-1.061e-6" izz="0.002"/>
      <!-- <inertia ixx="0.007" ixy="3.989e-7" ixz="-0.002" iyy="0.007" iyz="-1.061e-6" izz="0.002"/> -->
      <!-- <inertia ixx="0" ixy="0.0" ixz="0.0" iyy="0" iyz="0.0" izz="0"/> -->
    </inertial>
  </link>
  <link name="optimo_link5"/>
  <link name="optimo_link5_passive">
    <visual>
      <geometry>
        <mesh filename="file:///home/dk/workspaces/plato_ws/install/optimo_description/share/optimo_description/meshes/link5.stl"/>
      </geometry>
      <material name="LightGrey">
        <color rgba="0.999 0.999 0.999 1.0"/>
      </material>
    </visual>
    <collision>
      <geometry>
        <mesh filename="file:///home/dk/workspaces/plato_ws/install/optimo_description/share/optimo_description/meshes/col5.stl"/>
      </geometry>
    </collision>
    <inertial>
      <origin xyz=".001262 0.085 0.008"/>
      <mass value="2.23"/>
      <inertia ixx="0.000932" ixy="0" ixz="0" iyy="0.000802" iyz="-0.000030" izz="0.000733"/>
      <!-- <inertia ixx="0" ixy="0.0" ixz="0.0" iyy="0" iyz="0.0" izz="0"/> -->
    </inertial>
  </link>
  <link name="optimo_link6"/>
  <link name="optimo_link6_passive">
    <visual>
      <geometry>
        <mesh filename="file:///home/dk/workspaces/plato_ws/install/optimo_description/share/optimo_description/meshes/link6.stl"/>
      </geometry>
      <material name="LightGrey">
        <color rgba="0.999 0.999 0.999 1.0"/>
      </material>
    </visual>
    <collision>
      <geometry>
        <mesh filename="file:///home/dk/workspaces/plato_ws/install/optimo_description/share/optimo_description/meshes/col6.stl"/>
      </geometry>
    </collision>
    <inertial>
      <origin xyz="0 -0.00007 0.010855"/>
      <mass value="1.138"/>
      <inertia ixx="0.000932" ixy="0" ixz="0" iyy="0.000802" iyz="-0.000030" izz="0.0007325"/>
      <!-- <inertia ixx="0" ixy="0.0" ixz="0.0" iyy="0" iyz="0.0" izz="0"/> -->
    </inertial>
  </link>
  <link name="optimo_link7"/>
  <link name="optimo_link7_passive">
    <visual>
      <geometry>
        <mesh filename="file:///home/dk/workspaces/plato_ws/install/optimo_description/share/optimo_description/meshes/link7.stl"/>
      </geometry>
      <material name="LightGrey">
        <color rgba="0.999 0.999 0.999 1.0"/>
      </material>
    </visual>
    <collision>
      <geometry>
        <mesh filename="file:///home/dk/workspaces/plato_ws/install/optimo_description/share/optimo_description/meshes/col7.stl"/>
      </geometry>
    </collision>
    <inertial>
      <origin xyz="0 0 0"/>
      <mass value="1"/>
      <inertia ixx="0.005541" ixy=".000045" ixz="0.000077" iyy="0.004779" iyz="0.000043" izz="0.001723"/>
      <!-- <inertia ixx="0" ixy="0.0" ixz="0.0" iyy="0" iyz="0.0" izz="0"/> -->
    </inertial>
  </link>
  <!-- Robot Joints -->
  <joint name="optimo_joint1" type="revolute">
    <origin rpy="0 0 0" xyz="0 0 0"/>
    <parent link="optimo_link0"/>
    <child link="optimo_link1"/>
    <axis xyz="0 0 1"/>
    <limit effort="79" lower="-2.86233997164" upper="2.91469984917" velocity="10"/>
  </joint>
  <joint name="optimo_joint1_passive" type="fixed">
    <origin rpy="1.5707963267948966 0 0" xyz="0 0 0"/>
    <parent link="optimo_link1"/>
    <child link="optimo_link1_passive"/>
  </joint>
  <joint name="optimo_joint2" type="revolute">
    <origin rpy="0 0 0" xyz="0 0 0"/>
    <parent link="optimo_link1_passive"/>
    <child link="optimo_link2"/>
    <axis xyz="0 0 1"/>
    <limit effort="95" lower="1.0471975506" upper="4.3633231275" velocity="10"/>
  </joint>
  <joint name="optimo_joint2_passive" type="fixed">
    <origin rpy="1.5707963267948966 0 0" xyz="0 0 0"/>
    <parent link="optimo_link2"/>
    <child link="optimo_link2_passive"/>
  </joint>
  <joint name="optimo_joint3" type="revolute">
    <origin rpy="0 0 0" xyz="0 0 0.4"/>
    <parent link="optimo_link2_passive"/>
    <child link="optimo_link3"/>
    <axis xyz="0 0 1"/>
    <limit effort="32" lower="-2.91469984917" upper="2.84488667913" velocity="10"/>
  </joint>
  <joint name="optimo_joint3_passive" type="fixed">
    <origin rpy="-1.5707963267948966 0 0" xyz="0 0 0"/>
    <parent link="optimo_link3"/>
    <child link="optimo_link3_passive"/>
  </joint>
  <joint name="optimo_joint4" type="revolute">
    <origin rpy="0 0 0" xyz="0 0 0"/>
    <parent link="optimo_link3_passive"/>
    <child link="optimo_link4"/>
    <axis xyz="0 0 1"/>
    <limit effort="40" lower="-2.53072741395" upper="2.53072741395" velocity="10"/>
  </joint>
  <joint name="optimo_joint4_passive" type="fixed">
    <origin rpy="1.5707963267948966 0 0" xyz="0 0 0"/>
    <parent link="optimo_link4"/>
    <child link="optimo_link4_passive"/>
  </joint>
  <joint name="optimo_joint5" type="revolute">
    <origin rpy="0 0 0" xyz="0 0 0.4"/>
    <parent link="optimo_link4_passive"/>
    <child link="optimo_link5"/>
    <axis xyz="0 0 1"/>
    <limit effort="15" lower="-2.9670597267" upper="2.9670597267" velocity="10"/>
  </joint>
  <joint name="optimo_joint5_passive" type="fixed">
    <origin rpy="-1.5707963267948966 0 0" xyz="0 0 0"/>
    <parent link="optimo_link5"/>
    <child link="optimo_link5_passive"/>
  </joint>
  <joint name="optimo_joint6" type="revolute">
    <origin rpy="0 0 0" xyz="0 0 0"/>
    <parent link="optimo_link5_passive"/>
    <child link="optimo_link6"/>
    <axis xyz="0 0 1"/>
    <limit effort="15" lower="-2.0943951012" upper="2.0943951012" velocity="10"/>
  </joint>
  <joint name="optimo_joint6_passive" type="fixed">
    <origin rpy="1.5707963267948966 0 0" xyz="0 0 0"/>
    <parent link="optimo_link6"/>
    <child link="optimo_link6_passive"/>
  </joint>
  <joint name="optimo_joint7" type="revolute">
    <origin rpy="0 0 0" xyz="0 0 0"/>
    <parent link="optimo_link6_passive"/>
    <child link="optimo_link7"/>
    <axis xyz="0 0 1"/>
    <limit effort="15" lower="-2.65290046152" upper="3.28121899188" velocity="10"/>
  </joint>
  <joint name="optimo_joint7_passive" type="fixed">
    <origin rpy="1.5707963267948966 0 0" xyz="0 0 0"/>
    <parent link="optimo_link7"/>
    <child link="optimo_link7_passive"/>
  </joint>
  <link name="plato_base_link"/>
  <joint name="plato_base_link_to_palm" type="fixed">
    <parent link="plato_base_link"/>
    <child link="plato_palm"/>
    <origin rpy="0.0 0 0" xyz="0 0 0"/>
  </joint>
  <link name="plato_palm">
    <visual>
      <origin rpy="0 -0 0" xyz="0 0 0"/>
      <geometry>
        <mesh filename="file:///home/dk/workspaces/plato_ws/install/plato_description/share/plato_description/meshes/plato/base_visual.stl"/>
      </geometry>
      <material name="base_material">
        <color rgba="0.89999999999999991118 0.89999999999999991118 0.89999999999999991118 1.0"/>
      </material>
    </visual>
    <collision>
      <origin rpy="0 -0 0" xyz="0 0 0"/>
      <geometry>
        <mesh filename="file:///home/dk/workspaces/plato_ws/install/plato_description/share/plato_description/meshes/plato/base_collision.stl"/>
      </geometry>
    </collision>
    <inertial>
      <origin rpy="0 0 0" xyz="0.045493179467456464071 0.00075885043291842098779 -0.00682767319963901477"/>
      <mass value="0.17280321549697399974"/>
      <inertia ixx="0.000124447216717875575" ixy="-2.1184002504334913161e-06" ixz="-5.2375390643355526047e-06" iyy="0.00022114103876778816297" iyz="2.4145885068302643992e-06" izz="0.00030593848378724351235"/>
    </inertial>
  </link>
  <!-- Finger 1 (Thumb) -->
  <link name="plato_f1_proxbracket">
    <visual>
      <origin rpy="0 -0 0" xyz="0 0 0"/>
      <geometry>
        <mesh filename="file:///home/dk/workspaces/plato_ws/install/plato_description/share/plato_description/meshes/plato/proxbracket_visual.stl"/>
      </geometry>
      <material name="proxbracket_material">
        <color rgba="0.9000000000000000222 0.9000000000000000222 0.9000000000000000222 1.0"/>
      </material>
    </visual>
    <collision>
      <origin rpy="0 -0 0" xyz="0 0 0"/>
      <geometry>
        <mesh filename="file:///home/dk/workspaces/plato_ws/install/plato_description/share/plato_description/meshes/plato/proxbracket_collision.stl"/>
      </geometry>
    </collision>
    <inertial>
      <origin rpy="0 0 0" xyz="-0.0079504685553139688853 -0.013983661603934150613 -0.0095130973110596206421"/>
      <mass value="0.12656081824380860379"/>
      <inertia ixx="3.5117165939882084044e-05" ixy="-1.3052140141476243181e-05" ixz="1.9957519826334250588e-07" iyy="1.7537495218030365739e-05" iyz="-4.9180486622828042765e-07" izz="4.2451494821237482414e-05"/>
    </inertial>
  </link>
  <link name="plato_f1_prox">
    <visual>
      <origin rpy="0 -0 0" xyz="0 0 0"/>
      <geometry>
        <mesh filename="file:///home/dk/workspaces/plato_ws/install/plato_description/share/plato_description/meshes/plato/prox_visual.stl"/>
      </geometry>
      <material name="prox_material">
        <color rgba="0.9000000000000000222 0.9000000000000000222 0.9000000000000000222 1.0"/>
      </material>
    </visual>
    <collision>
      <origin rpy="0 -0 0" xyz="0 0 0"/>
      <geometry>
        <mesh filename="file:///home/dk/workspaces/plato_ws/install/plato_description/share/plato_description/meshes/plato/prox_collision.stl"/>
      </geometry>
    </collision>
    <inertial>
      <origin rpy="0 0 0" xyz="0.0020817714488827496026 3.9659156972864230043e-10 -0.015795112278833203096"/>
      <mass value="0.069114549940711839104"/>
      <inertia ixx="5.8883565545031638029e-06" ixy="-9.2074790702963013961e-09" ixz="-1.1640174651110935915e-06" iyy="9.6829622072775541655e-06" iyz="-9.4322537406537712947e-14" izz="9.2871592762525393485e-06"/>
    </inertial>
  </link>
  <link name="plato_f1_mid">
    <visual>
      <origin rpy="0 -0 0" xyz="0 0 0"/>
      <geometry>
        <mesh filename="file:///home/dk/workspaces/plato_ws/install/plato_description/share/plato_description/meshes/plato/mid_visual.stl"/>
      </geometry>
      <material name="mid_material">
        <color rgba="0.89999999999999991118 0.89999999999999991118 0.89999999999999991118 1.0"/>
      </material>
    </visual>
    <collision>
      <origin rpy="0 -0 0" xyz="0 0 0"/>
      <geometry>
        <mesh filename="file:///home/dk/workspaces/plato_ws/install/plato_description/share/plato_description/meshes/plato/mid_collision.stl"/>
      </geometry>
    </collision>
    <inertial>
      <origin rpy="0 0 0" xyz="0.02083906332658447616 -0.00066661768468519438241 -0.0023008505382949022595"/>
      <mass value="0.0080671501064400220893"/>
      <inertia ixx="2.1185571765449022898e-07" ixy="3.6426243959716221213e-08" ixz="-1.3233834119316724662e-10" iyy="1.2852102149793263521e-06" iyz="-3.1084190127067859768e-11" izz="1.3237276294092989039e-06"/>
    </inertial>
  </link>
  <link name="plato_f1_ee_frame">
        </link>
  <joint name="plato_f1_pip_pitch" type="revolute">
    <origin rpy="6.6672023420374162248e-16 1.5291665303066472343e-16 3.3306690741059185714e-16" xyz="0.048000000000000028755 6.9388939039072283776e-18 -0.0026999999999999871325"/>
    <parent link="plato_f1_prox"/>
    <child link="plato_f1_mid"/>
    <axis xyz="0 0 1"/>
    <limit effort="0.04" lower="-2.0944" upper="2.0944" velocity="5"/>
    <joint_properties friction="0.0"/>
  </joint>
  <joint name="plato_f1_mcp_pitch" type="revolute">
    <origin rpy="-2.8657554781383847745e-16 -1.5707963267948961139 0" xyz="-0.0049999999999999697464 -0.028150000000000133249 -0.0098999999999999366285"/>
    <parent link="plato_f1_proxbracket"/>
    <child link="plato_f1_prox"/>
    <axis xyz="0 0 1"/>
    <limit effort="0.04" lower="-2.0943951023931952626" upper="0.52359877559829881566" velocity="5"/>
    <joint_properties friction="0.0"/>
  </joint>
  <joint name="plato_f1_mcp_roll" type="revolute">
    <origin rpy="1.5707963267948958919 -2.5535129566378612263e-15 1.5707963267948938935" xyz="0.084500000000000047296 0.029999999999999988481 -0.033000000000000008493"/>
    <parent link="plato_palm"/>
    <child link="plato_f1_proxbracket"/>
    <axis xyz="0 0 1"/>
    <limit effort="0.04" lower="-0.52359877559829881566" upper="1.0471975511965976313" velocity="5"/>
    <joint_properties friction="0.0"/>
  </joint>
  <joint name="plato_f1_ee_joint" type="fixed">
    <origin rpy="-1.5707 0.0 0.0" xyz="0.05060 0.0 0.0"/>
    <parent link="plato_f1_mid"/>
    <child link="plato_f1_ee_frame"/>
  </joint>
  <!-- Finger 2 (Index) -->
  <link name="plato_f2_proxbracket">
    <visual>
      <origin rpy="0 -0 0" xyz="0 0 0"/>
      <geometry>
        <mesh filename="file:///home/dk/workspaces/plato_ws/install/plato_description/share/plato_description/meshes/plato/proxbracket_2_visual.stl"/>
      </geometry>
      <material name="proxbracket_2_material">
        <color rgba="0.9000000000000000222 0.9000000000000000222 0.9000000000000000222 1.0"/>
      </material>
    </visual>
    <collision>
      <origin rpy="0 -0 0" xyz="0 0 0"/>
      <geometry>
        <mesh filename="file:///home/dk/workspaces/plato_ws/install/plato_description/share/plato_description/meshes/plato/proxbracket_2_collision.stl"/>
      </geometry>
    </collision>
    <inertial>
      <origin rpy="0 0 0" xyz="-0.0079504685553134692849 -0.01398366160393426337 -0.0095130973110598305437"/>
      <mass value="0.12656081824380860379"/>
      <inertia ixx="3.5117165939882477067e-05" ixy="-1.305214014147555539e-05" ixz="1.9957519826318953702e-07" iyy="1.7537495218029413674e-05" iyz="-4.9180486622862919346e-07" izz="4.2451494821237075838e-05"/>
    </inertial>
  </link>
  <link name="plato_f2_prox">
    <visual>
      <origin rpy="0 -0 0" xyz="0 0 0"/>
      <geometry>
        <mesh filename="file:///home/dk/workspaces/plato_ws/install/plato_description/share/plato_description/meshes/plato/prox_2_visual.stl"/>
      </geometry>
      <material name="prox_2_material">
        <color rgba="0.9000000000000000222 0.9000000000000000222 0.9000000000000000222 1.0"/>
      </material>
    </visual>
    <collision>
      <origin rpy="0 -0 0" xyz="0 0 0"/>
      <geometry>
        <mesh filename="file:///home/dk/workspaces/plato_ws/install/plato_description/share/plato_description/meshes/plato/prox_2_collision.stl"/>
      </geometry>
    </collision>
    <inertial>
      <origin rpy="0 0 0" xyz="0.0020817714488827318217 -3.9659157728695655077e-10 0.013295112278833310163"/>
      <mass value="0.069114549940711839104"/>
      <inertia ixx="5.8883565545030553827e-06" ixy="9.2074790702970640566e-09" ixz="1.164017465111112438e-06" iyy="9.6829622072775270604e-06" iyz="-9.4322531718453391682e-14" izz="9.2871592762523818003e-06"/>
    </inertial>
  </link>
  <link name="plato_f2_mid">
    <visual>
      <origin rpy="0 -0 0" xyz="0 0 0"/>
      <geometry>
        <mesh filename="file:///home/dk/workspaces/plato_ws/install/plato_description/share/plato_description/meshes/plato/mid_2_visual.stl"/>
      </geometry>
      <material name="mid_2_material">
        <color rgba="0.89999999999999991118 0.89999999999999991118 0.89999999999999991118 1.0"/>
      </material>
    </visual>
    <collision>
      <origin rpy="0 -0 0" xyz="0 0 0"/>
      <geometry>
        <mesh filename="file:///home/dk/workspaces/plato_ws/install/plato_description/share/plato_description/meshes/plato/mid_2_collision.stl"/>
      </geometry>
    </collision>
    <inertial>
      <origin rpy="0 0 0" xyz="0.020839063326584340852 0.00066661768468522192115 -0.0022991494617051059027"/>
      <mass value="0.0080671501064400220893"/>
      <inertia ixx="2.1185571765448480268e-07" ixy="-3.6426243959717557937e-08" ixz="1.3233834119313656339e-10" iyy="1.2852102149793043292e-06" iyz="-3.1084190128060967641e-11" izz="1.3237276294092734929e-06"/>
    </inertial>
  </link>
  <link name="plato_f2_ee_frame">
        </link>
  <joint name="plato_f2_pip_pitch" type="revolute">
    <origin rpy="8.673617379890070258e-17 5.7824115865889863811e-17 -1.5021026917775434348e-15" xyz="0.047999999999999792832 0 0.0047999999999999813649"/>
    <parent link="plato_f2_prox"/>
    <child link="plato_f2_mid"/>
    <axis xyz="0 0 1"/>
    <limit effort="0.04" lower="-2.0944" upper="2.0944" velocity="5"/>
    <joint_properties friction="0.0"/>
  </joint>
  <joint name="plato_f2_mcp_pitch" type="revolute">
    <origin rpy="-1.570796326794896558 6.9017807609091964755e-16 -1.5707963267948907848" xyz="-0.0024999999999990307753 -0.028150000000000355294 -0.0099000000000003564316"/>
    <parent link="plato_f2_proxbracket"/>
    <child link="plato_f2_prox"/>
    <axis xyz="0 0 1"/>
    <limit effort="0.04" lower="-1.570796326794896558" upper="0.785398163397448279" velocity="5"/>
    <joint_properties friction="0.0"/>
  </joint>
  <joint name="plato_f2_mcp_yaw" type="revolute">
    <origin rpy="3.141592653589793116 -1.1714553645825245089e-15 -1.5707963267948998887" xyz="0.1000000000000001027 0.029999999999999974604 -0.015000000000000013323"/>
    <parent link="plato_palm"/>
    <child link="plato_f2_proxbracket"/>
    <axis xyz="0 0 1"/>
    <limit effort="0.04" lower="-1.570796326794896558" upper="0.26179938779914940783" velocity="5"/>
    <joint_properties friction="0.0"/>
  </joint>
  <joint name="plato_f2_ee_joint" type="fixed">
    <origin rpy="-1.5707 0.0 0.0" xyz="0.05060 0.0 0.0"/>
    <parent link="plato_f2_mid"/>
    <child link="plato_f2_ee_frame"/>
  </joint>
  <!-- Finger 3: Middle -->
  <link name="plato_f3_proxbracket">
    <visual>
      <origin rpy="0 -0 0" xyz="0 0 0"/>
      <geometry>
        <mesh filename="file:///home/dk/workspaces/plato_ws/install/plato_description/share/plato_description/meshes/plato/proxbracket_3_visual.stl"/>
      </geometry>
      <material name="proxbracket_3_material">
        <color rgba="0.9000000000000000222 0.9000000000000000222 0.9000000000000000222 1.0"/>
      </material>
    </visual>
    <collision>
      <origin rpy="0 -0 0" xyz="0 0 0"/>
      <geometry>
        <mesh filename="file:///home/dk/workspaces/plato_ws/install/plato_description/share/plato_description/meshes/plato/proxbracket_3_collision.stl"/>
      </geometry>
    </collision>
    <inertial>
      <origin rpy="0 0 0" xyz="-0.0079504685553140486826 -0.013983661603934124593 -0.0095130973110597195214"/>
      <mass value="0.12656081824380860379"/>
      <inertia ixx="3.5117165939882016281e-05" ixy="-1.3052140141476346519e-05" ixz="1.9957519826327045514e-07" iyy="1.7537495218030480935e-05" iyz="-4.9180486622843035248e-07" izz="4.2451494821237509519e-05"/>
    </inertial>
  </link>
  <link name="plato_f3_prox">
    <visual>
      <origin rpy="0 -0 0" xyz="0 0 0"/>
      <geometry>
        <mesh filename="file:///home/dk/workspaces/plato_ws/install/plato_description/share/plato_description/meshes/plato/prox_3_visual.stl"/>
      </geometry>
      <material name="prox_3_material">
        <color rgba="0.9000000000000000222 0.9000000000000000222 0.9000000000000000222 1.0"/>
      </material>
    </visual>
    <collision>
      <origin rpy="0 -0 0" xyz="0 0 0"/>
      <geometry>
        <mesh filename="file:///home/dk/workspaces/plato_ws/install/plato_description/share/plato_description/meshes/plato/prox_3_collision.stl"/>
      </geometry>
    </collision>
    <inertial>
      <origin rpy="0 0 0" xyz="0.0020817714488827331228 -3.9659157098710811182e-10 0.013295112278833216488"/>
      <mass value="0.069114549940711839104"/>
      <inertia ixx="5.8883565545029046108e-06" ixy="9.2074790703146002856e-09" ixz="1.1640174651110802507e-06" iyy="9.6829622072771458956e-06" iyz="-9.4322525854387518435e-14" izz="9.2871592762523953529e-06"/>
    </inertial>
  </link>
  <link name="plato_f3_mid">
    <visual>
      <origin rpy="0 -0 0" xyz="0 0 0"/>
      <geometry>
        <mesh filename="file:///home/dk/workspaces/plato_ws/install/plato_description/share/plato_description/meshes/plato/mid_3_visual.stl"/>
      </geometry>
      <material name="mid_3_material">
        <color rgba="0.89999999999999991118 0.89999999999999991118 0.89999999999999991118 1.0"/>
      </material>
    </visual>
    <collision>
      <origin rpy="0 -0 0" xyz="0 0 0"/>
      <geometry>
        <mesh filename="file:///home/dk/workspaces/plato_ws/install/plato_description/share/plato_description/meshes/plato/mid_3_collision.stl"/>
      </geometry>
    </collision>
    <inertial>
      <origin rpy="0 0 0" xyz="0.020839063326584514324 0.00066661768468518982876 -0.0022991494617050798818"/>
      <mass value="0.0080671501064400220893"/>
      <inertia ixx="2.1185571765449242598e-07" ixy="-3.6426243959717088098e-08" ixz="1.3233834119147816966e-10" iyy="1.2852102149793367282e-06" iyz="-3.1084190127996925767e-11" izz="1.3237276294093048331e-06"/>
    </inertial>
  </link>
  <link name="plato_f3_ee_frame">
        </link>
  <joint name="plato_f3_pip_pitch" type="revolute">
    <origin rpy="-1.9081958235950694314e-16 5.7824115816011125546e-17 1.7763568393717672612e-15" xyz="0.047999999999998654854 2.0122792321330962295e-16 0.0047999999999999917732"/>
    <parent link="plato_f3_prox"/>
    <child link="plato_f3_mid"/>
    <axis xyz="0 0 1"/>
    <limit effort="0.04" lower="-2.0944" upper="2.0944" velocity="5"/>
    <joint_properties friction="0.0"/>
  </joint>
  <joint name="plato_f3_mcp_pitch" type="revolute">
    <origin rpy="-1.570796326794896558 -3.7816971775725042188e-15 -1.5707963267948943376" xyz="-0.002500000000000099365 -0.028150000000000077738 -0.0099000000000001291828"/>
    <parent link="plato_f3_proxbracket"/>
    <child link="plato_f3_prox"/>
    <axis xyz="0 0 1"/>
    <limit effort="0.04" lower="-1.570796326794896558" upper="0.785398163397448279" velocity="5"/>
    <joint_properties friction="0.0"/>
  </joint>
  <joint name="plato_f3_mcp_yaw" type="revolute">
    <origin rpy="-3.1415926535897926719 1.1057720720235713428e-16 -1.5707963267948983344" xyz="0.10000000000000000555 -0.029999999999999964195 -0.015000000000000048017"/>
    <parent link="plato_palm"/>
    <child link="plato_f3_proxbracket"/>
    <axis xyz="0 0 1"/>
    <limit effort="0.04" lower="-0.26179938779914940783" upper="0.785398163397448279" velocity="5"/>
    <joint_properties friction="0.0"/>
  </joint>
  <joint name="plato_f3_ee_joint" type="fixed">
    <origin rpy="-1.5707 0.0 0.0" xyz="0.05060 0.0 0.0"/>
    <parent link="plato_f3_mid"/>
    <child link="plato_f3_ee_frame"/>
  </joint>
  <!-- Connect PLATO Hand to Optimo Arm -->
  <joint name="hand_arm_joint" type="fixed">
    <parent link="optimo_link7_passive"/>
    <child link="plato_base_link"/>
    <origin rpy="1.5707 0 1.5707" xyz="0 0.16 0"/>
  </joint>

</robot>
