<?xml version="1.0" ?>
<!-- =================================================================================== -->
<!-- |    This document was autogenerated by xacro from optimo.urdf.xacro              | -->
<!-- |    EDITING THIS FILE BY HAND IS NOT RECOMMENDED                                 | -->
<!-- =================================================================================== -->
<robot name="optimo">
  <link name="optimo_base_link">
    </link>
  <joint name="optimo_base_joint" type="fixed">
    <parent link="optimo_base_link"/>
    <child link="optimo_link0"/>
    <origin rpy="0 0 0" xyz="0 0 0.27"/>
  </joint>
  <!-- Robot Links -->
  <link name="optimo_link0">
    <visual>
      <geometry>
        <mesh filename="file:///home/dk/workspaces/plato_ws/install/optimo_description/share/optimo_description/meshes/link0.stl"/>
      </geometry>
      <material name="LightGrey">
        <color rgba="0.999 0.999 0.999 1.0"/>
      </material>
    </visual>
    <collision>
      <geometry>
        <mesh filename="file:///home/dk/workspaces/plato_ws/install/optimo_description/share/optimo_description/meshes/col0.stl"/>
      </geometry>
    </collision>
    <inertial>
      <!-- Doesn't matter, just placeholder values -->
      <origin xyz="0 0 0"/>
      <mass value="1"/>
      <inertia ixx="0" ixy="0.0" ixz="0.0" iyy="0" iyz="0.0" izz="0"/>
    </inertial>
  </link>
  <link name="optimo_link1">
    <visual>
      <geometry>
        <sphere radius="0.01"/>
      </geometry>
      <material name="LightGrey">
        <color rgba="0.999 0.999 0.999 1.0"/>
      </material>
    </visual>
  </link>
  <link name="optimo_link1_passive">
    <visual>
      <geometry>
        <mesh filename="file:///home/dk/workspaces/plato_ws/install/optimo_description/share/optimo_description/meshes/link1.stl"/>
      </geometry>
      <material name="LightGrey">
        <color rgba="0.999 0.999 0.999 1.0"/>
      </material>
    </visual>
    <collision>
      <geometry>
        <mesh filename="file:///home/dk/workspaces/plato_ws/install/optimo_description/share/optimo_description/meshes/col1.stl"/>
      </geometry>
    </collision>
    <inertial>
      <origin xyz="0 -0.01635 0.01549"/>
      <mass value="4.152"/>
      <inertia ixx="0.01" ixy="0.000017" ixz="-.00001" iyy="0.007494" iyz="0.0000213" izz="0.009939"/>
      <!-- <inertia ixx="0" ixy="0.0" ixz="0.0" iyy="0" iyz="0.0" izz="0"/> -->
    </inertial>
  </link>
  <link name="optimo_link2"/>
  <link name="optimo_link2_passive">
    <visual>
      <geometry>
        <mesh filename="file:///home/dk/workspaces/plato_ws/install/optimo_description/share/optimo_description/meshes/link2.stl"/>
      </geometry>
      <material name="LightGrey">
        <color rgba="0.999 0.999 0.999 1.0"/>
      </material>
    </visual>
    <collision>
      <geometry>
        <mesh filename="file:///home/dk/workspaces/plato_ws/install/optimo_description/share/optimo_description/meshes/col2.stl"/>
      </geometry>
    </collision>
    <inertial>
      <origin rpy="0 0 3.1415926518" xyz="0 -0.05063 0.05677"/>
      <mass value="1.72"/>
      <inertia ixx="0.005694" ixy="0" ixz="0" iyy="0.005902" iyz="-0.001353" izz="0.002415"/>
      <!-- <inertia ixx="0" ixy="0.0" ixz="0.0" iyy="0" iyz="0.0" izz="0"/> -->
    </inertial>
  </link>
  <link name="optimo_link3"/>
  <link name="optimo_link3_passive">
    <visual>
      <geometry>
        <mesh filename="file:///home/dk/workspaces/plato_ws/install/optimo_description/share/optimo_description/meshes/link3.stl"/>
      </geometry>
      <material name="LightGrey">
        <color rgba="0.999 0.999 0.999 1.0"/>
      </material>
    </visual>
    <collision>
      <geometry>
        <mesh filename="file:///home/dk/workspaces/plato_ws/install/optimo_description/share/optimo_description/meshes/col3.stl"/>
      </geometry>
    </collision>
    <inertial>
      <!-- Inertia values taken from yaml, but these seem like they cannot be accurate...-->
      <origin xyz="-0.000039 .098 0"/>
      <mass value="4.310"/>
      <inertia ixx="0.012989" ixy="-0.000015" ixz="-.000003" iyy="0.002584" iyz="0.000632" izz="0.01305"/>
      <!-- <inertia ixx="0" ixy="0.0" ixz="0.0" iyy="0" iyz="0.0" izz="0"/> -->
    </inertial>
  </link>
  <link name="optimo_link4"/>
  <link name="optimo_link4_passive">
    <origin rpy="0 0 0" xyz="0 0 0"/>
    <visual>
      <geometry>
        <mesh filename="file:///home/dk/workspaces/plato_ws/install/optimo_description/share/optimo_description/meshes/link4.stl"/>
      </geometry>
      <material name="LightGrey">
        <color rgba="0.999 0.999 0.999 1.0"/>
      </material>
    </visual>
    <collision>
      <geometry>
        <mesh filename="file:///home/dk/workspaces/plato_ws/install/optimo_description/share/optimo_description/meshes/col4.stl"/>
      </geometry>
    </collision>
    <inertial>
      <origin rpy="0 0 0" xyz="-.00001 0.048852 0.0688"/>
      <mass value="1.09"/>
      <inertia ixx="0.007" ixy="-3.989e-7" ixz="0.002" iyy="0.007" iyz="-1.061e-6" izz="0.002"/>
      <!-- <inertia ixx="0.007" ixy="3.989e-7" ixz="-0.002" iyy="0.007" iyz="-1.061e-6" izz="0.002"/> -->
      <!-- <inertia ixx="0" ixy="0.0" ixz="0.0" iyy="0" iyz="0.0" izz="0"/> -->
    </inertial>
  </link>
  <link name="optimo_link5"/>
  <link name="optimo_link5_passive">
    <visual>
      <geometry>
        <mesh filename="file:///home/dk/workspaces/plato_ws/install/optimo_description/share/optimo_description/meshes/link5.stl"/>
      </geometry>
      <material name="LightGrey">
        <color rgba="0.999 0.999 0.999 1.0"/>
      </material>
    </visual>
    <collision>
      <geometry>
        <mesh filename="file:///home/dk/workspaces/plato_ws/install/optimo_description/share/optimo_description/meshes/col5.stl"/>
      </geometry>
    </collision>
    <inertial>
      <origin xyz=".001262 0.085 0.008"/>
      <mass value="2.23"/>
      <inertia ixx="0.000932" ixy="0" ixz="0" iyy="0.000802" iyz="-0.000030" izz="0.000733"/>
      <!-- <inertia ixx="0" ixy="0.0" ixz="0.0" iyy="0" iyz="0.0" izz="0"/> -->
    </inertial>
  </link>
  <link name="optimo_link6"/>
  <link name="optimo_link6_passive">
    <visual>
      <geometry>
        <mesh filename="file:///home/dk/workspaces/plato_ws/install/optimo_description/share/optimo_description/meshes/link6.stl"/>
      </geometry>
      <material name="LightGrey">
        <color rgba="0.999 0.999 0.999 1.0"/>
      </material>
    </visual>
    <collision>
      <geometry>
        <mesh filename="file:///home/dk/workspaces/plato_ws/install/optimo_description/share/optimo_description/meshes/col6.stl"/>
      </geometry>
    </collision>
    <inertial>
      <origin xyz="0 -0.00007 0.010855"/>
      <mass value="1.138"/>
      <inertia ixx="0.000932" ixy="0" ixz="0" iyy="0.000802" iyz="-0.000030" izz="0.0007325"/>
      <!-- <inertia ixx="0" ixy="0.0" ixz="0.0" iyy="0" iyz="0.0" izz="0"/> -->
    </inertial>
  </link>
  <link name="optimo_link7"/>
  <link name="optimo_link7_passive">
    <visual>
      <geometry>
        <mesh filename="file:///home/dk/workspaces/plato_ws/install/optimo_description/share/optimo_description/meshes/link7.stl"/>
      </geometry>
      <material name="LightGrey">
        <color rgba="0.999 0.999 0.999 1.0"/>
      </material>
    </visual>
    <collision>
      <geometry>
        <mesh filename="file:///home/dk/workspaces/plato_ws/install/optimo_description/share/optimo_description/meshes/col7.stl"/>
      </geometry>
    </collision>
    <inertial>
      <origin xyz="0 0 0"/>
      <mass value="1"/>
      <inertia ixx="0.005541" ixy=".000045" ixz="0.000077" iyy="0.004779" iyz="0.000043" izz="0.001723"/>
      <!-- <inertia ixx="0" ixy="0.0" ixz="0.0" iyy="0" iyz="0.0" izz="0"/> -->
    </inertial>
  </link>
  <!-- Robot Joints -->
  <joint name="optimo_joint1" type="revolute">
    <origin rpy="0 0 0" xyz="0 0 0"/>
    <parent link="optimo_link0"/>
    <child link="optimo_link1"/>
    <axis xyz="0 0 1"/>
    <limit effort="79" lower="-2.86233997164" upper="2.91469984917" velocity="10"/>
  </joint>
  <joint name="optimo_joint1_passive" type="fixed">
    <origin rpy="1.5707963267948966 0 0" xyz="0 0 0"/>
    <parent link="optimo_link1"/>
    <child link="optimo_link1_passive"/>
  </joint>
  <joint name="optimo_joint2" type="revolute">
    <origin rpy="0 0 0" xyz="0 0 0"/>
    <parent link="optimo_link1_passive"/>
    <child link="optimo_link2"/>
    <axis xyz="0 0 1"/>
    <limit effort="95" lower="1.0471975506" upper="4.3633231275" velocity="10"/>
  </joint>
  <joint name="optimo_joint2_passive" type="fixed">
    <origin rpy="1.5707963267948966 0 0" xyz="0 0 0"/>
    <parent link="optimo_link2"/>
    <child link="optimo_link2_passive"/>
  </joint>
  <joint name="optimo_joint3" type="revolute">
    <origin rpy="0 0 0" xyz="0 0 0.4"/>
    <parent link="optimo_link2_passive"/>
    <child link="optimo_link3"/>
    <axis xyz="0 0 1"/>
    <limit effort="32" lower="-2.91469984917" upper="2.84488667913" velocity="10"/>
  </joint>
  <joint name="optimo_joint3_passive" type="fixed">
    <origin rpy="-1.5707963267948966 0 0" xyz="0 0 0"/>
    <parent link="optimo_link3"/>
    <child link="optimo_link3_passive"/>
  </joint>
  <joint name="optimo_joint4" type="revolute">
    <origin rpy="0 0 0" xyz="0 0 0"/>
    <parent link="optimo_link3_passive"/>
    <child link="optimo_link4"/>
    <axis xyz="0 0 1"/>
    <limit effort="40" lower="-2.53072741395" upper="2.53072741395" velocity="10"/>
  </joint>
  <joint name="optimo_joint4_passive" type="fixed">
    <origin rpy="1.5707963267948966 0 0" xyz="0 0 0"/>
    <parent link="optimo_link4"/>
    <child link="optimo_link4_passive"/>
  </joint>
  <joint name="optimo_joint5" type="revolute">
    <origin rpy="0 0 0" xyz="0 0 0.4"/>
    <parent link="optimo_link4_passive"/>
    <child link="optimo_link5"/>
    <axis xyz="0 0 1"/>
    <limit effort="15" lower="-2.9670597267" upper="2.9670597267" velocity="10"/>
  </joint>
  <joint name="optimo_joint5_passive" type="fixed">
    <origin rpy="-1.5707963267948966 0 0" xyz="0 0 0"/>
    <parent link="optimo_link5"/>
    <child link="optimo_link5_passive"/>
  </joint>
  <joint name="optimo_joint6" type="revolute">
    <origin rpy="0 0 0" xyz="0 0 0"/>
    <parent link="optimo_link5_passive"/>
    <child link="optimo_link6"/>
    <axis xyz="0 0 1"/>
    <limit effort="15" lower="-2.0943951012" upper="2.0943951012" velocity="10"/>
  </joint>
  <joint name="optimo_joint6_passive" type="fixed">
    <origin rpy="1.5707963267948966 0 0" xyz="0 0 0"/>
    <parent link="optimo_link6"/>
    <child link="optimo_link6_passive"/>
  </joint>
  <joint name="optimo_joint7" type="revolute">
    <origin rpy="0 0 0" xyz="0 0 0"/>
    <parent link="optimo_link6_passive"/>
    <child link="optimo_link7"/>
    <axis xyz="0 0 1"/>
    <limit effort="15" lower="-2.65290046152" upper="3.28121899188" velocity="10"/>
  </joint>
  <joint name="optimo_joint7_passive" type="fixed">
    <origin rpy="1.5707963267948966 0 0" xyz="0 0 0"/>
    <parent link="optimo_link7"/>
    <child link="optimo_link7_passive"/>
  </joint>
</robot>
