<?xml version="1.0"?>
<robot name="plato" xmlns:xacro="http://www.ros.org/wiki/xacro">

<link name="base_link">
</link>

<joint name = "base_link_to_palm" type="fixed">
    <origin xyz="0 0 0" rpy="0 0 0"/>
    <parent link="base_link"/>
    <child link="base"/>
</joint>

<link name="base">
<visual>
<origin xyz="3.4694469519536141888e-18 0 -0.016000000000000000333" rpy="9.0205620750793734716e-17 2.7644301800592740999e-17 -6.8593115106840873102e-16" />
<geometry>
<mesh filename="package://optimo_description/meshes/plato/wrist.stl"/>
</geometry>
<material name="wrist_material">
<color rgba="0.91764705882352937127 0.91764705882352937127 0.91764705882352937127 1.0"/>
</material>
</visual>
<collision>
<origin xyz="3.4694469519536141888e-18 0 -0.016000000000000000333" rpy="9.0205620750793734716e-17 2.7644301800592740999e-17 -6.8593115106840873102e-16" />
<geometry>
<mesh filename="package://optimo_description/meshes/plato/wrist.stl"/>
</geometry>
</collision>
<visual>
<origin xyz="3.4694469519536141888e-18 0 -0.016000000000000000333" rpy="9.0205620750793734716e-17 2.7644301800592740999e-17 -6.8593115106840873102e-16" />
<geometry>
<mesh filename="package://optimo_description/meshes/plato/palm.stl"/>
</geometry>
<material name="palm_material">
<color rgba="0.90196078431372550543 0.90196078431372550543 0.90196078431372550543 1.0"/>
</material>
</visual>
<collision>
<origin xyz="3.4694469519536141888e-18 0 -0.016000000000000000333" rpy="9.0205620750793734716e-17 2.7644301800592740999e-17 -6.8593115106840873102e-16" />
<geometry>
<mesh filename="package://optimo_description/meshes/plato/palm.stl"/>
</geometry>
</collision>
<visual>
<origin xyz="-1.3788241001829422089e-16 -2.7755575615628913511e-17 -0.016000000000000028089" rpy="1.6653345369377128704e-16 -6.1550287343936601898e-16 -4.3977943457854727703e-15" />
<geometry>
<mesh filename="package://optimo_description/meshes/plato/thumb_roll.stl"/>
</geometry>
<material name="thumb_roll_material">
<color rgba="0.61568627450980395466 0.81176470588235294379 0.92941176470588238168 1.0"/>
</material>
</visual>
<collision>
<origin xyz="-1.3788241001829422089e-16 -2.7755575615628913511e-17 -0.016000000000000028089" rpy="1.6653345369377128704e-16 -6.1550287343936601898e-16 -4.3977943457854727703e-15" />
<geometry>
<mesh filename="package://optimo_description/meshes/plato/thumb_roll.stl"/>
</geometry>
</collision>
<inertial>
<origin xyz="-0.0007588504329184387687 0.045493179467456477949 -0.0068276731996390008922" rpy="0 0 0"/>
<mass value="0.1728032154969740275" />
<inertia ixx="0.00022114103876778821718" ixy="2.1184002504335696667e-06"  ixz="-2.4145885068302762577e-06" iyy="0.000124447216717875575" iyz="-5.2375390643356322257e-06" izz="0.00030593848378724351235" />
</inertial>
</link>

<link name="mcp_yaw">
<visual>
<origin xyz="3.4694469519536141888e-18 1.3877787807814456755e-17 -0.0098999999999999990785" rpy="3.141592653589793116 -1.8219420127185215539e-33 -1.0018951972865276753e-32" />
<geometry>
<mesh filename="package://optimo_description/meshes/plato/motor.stl"/>
</geometry>
<material name="motor_material">
<color rgba="0.90196078431372550543 0.90196078431372550543 0.90196078431372550543 1.0"/>
</material>
</visual>
<collision>
<origin xyz="3.4694469519536141888e-18 1.3877787807814456755e-17 -0.0098999999999999990785" rpy="3.141592653589793116 -1.8219420127185215539e-33 -1.0018951972865276753e-32" />
<geometry>
<mesh filename="package://optimo_description/meshes/plato/motor.stl"/>
</geometry>
</collision>
<visual>
<origin xyz="-0.014900000000000123215 0.028149999999999508749 -0.0099000000000003078593" rpy="-3.9443456428854888764e-30 1.5707963267948943376 0" />
<geometry>
<mesh filename="package://optimo_description/meshes/plato/motor.stl"/>
</geometry>
<material name="motor_material">
<color rgba="0.90196078431372550543 0.90196078431372550543 0.90196078431372550543 1.0"/>
</material>
</visual>
<collision>
<origin xyz="-0.014900000000000123215 0.028149999999999508749 -0.0099000000000003078593" rpy="-3.9443456428854888764e-30 1.5707963267948943376 0" />
<geometry>
<mesh filename="package://optimo_description/meshes/plato/motor.stl"/>
</geometry>
</collision>
<visual>
<origin xyz="-6.9388939039072283776e-18 1.3877787807814456755e-17 -0.019799999999999998157" rpy="-3.1415926535897922278 -1.6363862086693127369e-16 -3.141592653589793116" />
<geometry>
<mesh filename="package://optimo_description/meshes/plato/mcp_yaw_connect.stl"/>
</geometry>
<material name="mcp_yaw_connect_material">
<color rgba="0.90196078431372550543 0.90196078431372550543 0.90196078431372550543 1.0"/>
</material>
</visual>
<collision>
<origin xyz="-6.9388939039072283776e-18 1.3877787807814456755e-17 -0.019799999999999998157" rpy="-3.1415926535897922278 -1.6363862086693127369e-16 -3.141592653589793116" />
<geometry>
<mesh filename="package://optimo_description/meshes/plato/mcp_yaw_connect.stl"/>
</geometry>
</collision>
<inertial>
<origin xyz="-0.0079504685553140486826 0.013983661603933850506 -0.010286902688940493741" rpy="0 0 0"/>
<mass value="0.12656081824380860379" />
<inertia ixx="3.5117165939881067604e-05" ixy="1.3052140141476160172e-05"  ixz="-1.995751982634699314e-07" iyy="1.7537495218030352186e-05" iyz="-4.9180486622802420018e-07" izz="4.2451494821236167819e-05" />
</inertial>
</link>

<link name="mcp_pitch">
<visual>
<origin xyz="0 -2.6020852139652106416e-18 -0.016399999999999633621" rpy="1.0325074129013607149e-14 -4.2751324234174125628e-15 -1.570796326794896558" />
<geometry>
<mesh filename="package://optimo_description/meshes/plato/motor.stl"/>
</geometry>
<material name="motor_material">
<color rgba="0.90196078431372550543 0.90196078431372550543 0.90196078431372550543 1.0"/>
</material>
</visual>
<collision>
<origin xyz="0 -2.6020852139652106416e-18 -0.016399999999999633621" rpy="1.0325074129013607149e-14 -4.2751324234174125628e-15 -1.570796326794896558" />
<geometry>
<mesh filename="package://optimo_description/meshes/plato/motor.stl"/>
</geometry>
</collision>
<visual>
<origin xyz="0.019999999999999906741 -8.6736173798840354721e-19 -0.0049999999999999940326" rpy="1.570796326794896558 -1.570796326794896558 0" />
<geometry>
<mesh filename="package://optimo_description/meshes/plato/phlange.stl"/>
</geometry>
<material name="phlange_material">
<color rgba="0.90196078431372550543 0.90196078431372550543 0.90196078431372550543 1.0"/>
</material>
</visual>
<collision>
<origin xyz="0.019999999999999906741 -8.6736173798840354721e-19 -0.0049999999999999940326" rpy="1.570796326794896558 -1.570796326794896558 0" />
<geometry>
<mesh filename="package://optimo_description/meshes/plato/phlange.stl"/>
</geometry>
</collision>
<visual>
<origin xyz="0 -8.6736173798840354721e-19 0" rpy="1.570796326794896558 1.570796326794896558 0" />
<geometry>
<mesh filename="package://optimo_description/meshes/plato/mcp_pitch_connect.stl"/>
</geometry>
<material name="mcp_pitch_connect_material">
<color rgba="0.90196078431372550543 0.90196078431372550543 0.90196078431372550543 1.0"/>
</material>
</visual>
<collision>
<origin xyz="0 -8.6736173798840354721e-19 0" rpy="1.570796326794896558 1.570796326794896558 0" />
<geometry>
<mesh filename="package://optimo_description/meshes/plato/mcp_pitch_connect.stl"/>
</geometry>
</collision>
<inertial>
<origin xyz="0.0020817714488827365922 3.9659157887021715613e-10 -0.015795112278832897784" rpy="0 0 0"/>
<mass value="0.069114549940711825227" />
<inertia ixx="5.8883565545031231453e-06" ixy="-9.2074790703350845863e-09"  ixz="-1.1640174651109904652e-06" iyy="9.6829622072777303483e-06" iyz="-9.4322549796764935789e-14" izz="9.2871592762527697414e-06" />
</inertial>
</link>

<link name="pip">
<visual>
<origin xyz="0 0 -0.0022999999999999999611" rpy="1.570796326794896558 1.570796326794896558 0" />
<geometry>
<mesh filename="package://optimo_description/meshes/plato/pip_connect.stl"/>
</geometry>
<material name="pip_connect_material">
<color rgba="0.90196078431372550543 0.90196078431372550543 0.90196078431372550543 1.0"/>
</material>
</visual>
<collision>
<origin xyz="0 0 -0.0022999999999999999611" rpy="1.570796326794896558 1.570796326794896558 0" />
<geometry>
<mesh filename="package://optimo_description/meshes/plato/pip_connect.stl"/>
</geometry>
</collision>
<visual>
<origin xyz="0.029600000000000431521 -2.6801477703841669609e-16 -0.0023000000000002185363" rpy="1.57079632679489678 -1.570796326794896558 0" />
<geometry>
<mesh filename="package://optimo_description/meshes/plato/fingertip.stl"/>
</geometry>
<material name="fingertip_material">
<color rgba="0.90196078431372550543 0.90196078431372550543 0.90196078431372550543 1.0"/>
</material>
</visual>
<collision>
<origin xyz="0.029600000000000431521 -2.6801477703841669609e-16 -0.0023000000000002185363" rpy="1.57079632679489678 -1.570796326794896558 0" />
<geometry>
<mesh filename="package://optimo_description/meshes/plato/fingertip.stl"/>
</geometry>
</collision>
<visual>
<origin xyz="0.024000241812767941774 -0.030174068124402677465 -0.072096228994413036339" rpy="-3.8455702303801434139e-17 1.570796326794896558 0" />
<geometry>
<mesh filename="package://optimo_description/meshes/plato/ft_sensor.stl"/>
</geometry>
<material name="ft_sensor_material">
<color rgba="0.90196078431372550543 0.90196078431372550543 0.90196078431372550543 1.0"/>
</material>
</visual>
<collision>
<origin xyz="0.024000241812767941774 -0.030174068124402677465 -0.072096228994413036339" rpy="-3.8455702303801434139e-17 1.570796326794896558 0" />
<geometry>
<mesh filename="package://optimo_description/meshes/plato/ft_sensor.stl"/>
</geometry>
</collision>
<inertial>
<origin xyz="0.020839063326584635755 -0.00066661768468522094536 -0.0023008505382950436395" rpy="0 0 0"/>
<mass value="0.0080671501064400203546" />
<inertia ixx="2.1185571765449787875e-07" ixy="3.6426243959718411587e-08"  ixz="-1.3233834118458726401e-10" iyy="1.2852102149793485867e-06" iyz="-3.108419012789066537e-11" izz="1.3237276294093304559e-06" />
</inertial>
</link>

<joint name="f2_pip" type="revolute">
<origin xyz="0.047999999999998710365 0 -0.0027000000000000877465" rpy="8.6736173795253712333e-17 -1.1333526709686569771e-16 9.7660980066365267833e-26" />
<parent link="mcp_pitch" />
<child link="pip" />
<axis xyz="0 0 1"/>
<limit effort="1" velocity="20" lower="-2.0943951023931952626" upper="2.0943951023931952626"/>
<joint_properties friction="0.0"/>
</joint>

<joint name="f2_mcp_pitch" type="revolute">
<origin xyz="-0.0050000000000001397493 0.028149999999999536504 -0.0099000000000003061246" rpy="-1.57079632679489678 -2.7077043760675503572e-14 1.5707963267948823471" />
<parent link="mcp_yaw" />
<child link="mcp_pitch" />
<axis xyz="0 0 1"/>
<limit effort="1" velocity="20" lower="-1.570796326794896558" upper="1.570796326794896558"/>
<joint_properties friction="0.0"/>
</joint>

<joint name="f2_mcp_yaw" type="revolute">
<origin xyz="0.029999999999999912154 0.10000000000000003331 0.0050000000000003270995" rpy="5.8606965434539231359e-16 1.9351011260415344561e-16 -7.1054273576010255245e-15" />
<parent link="base" />
<child link="mcp_yaw" />
<axis xyz="0 0 1"/>
<limit effort="1" velocity="20" lower="-0.52359877559829881566" upper="0.26179938779914940783"/>
<joint_properties friction="0.0"/>
</joint>

<link name="mcp_yaw_2">
<visual>
<origin xyz="-3.4694469519536141888e-18 0 -0.0099000000000000008132" rpy="3.141592653589793116 -1.1374534524689678013e-32 1.389378947316507434e-31" />
<geometry>
<mesh filename="package://optimo_description/meshes/plato/motor.stl"/>
</geometry>
<material name="motor_material">
<color rgba="0.90196078431372550543 0.90196078431372550543 0.90196078431372550543 1.0"/>
</material>
</visual>
<collision>
<origin xyz="-3.4694469519536141888e-18 0 -0.0099000000000000008132" rpy="3.141592653589793116 -1.1374534524689678013e-32 1.389378947316507434e-31" />
<geometry>
<mesh filename="package://optimo_description/meshes/plato/motor.stl"/>
</geometry>
</collision>
<visual>
<origin xyz="-0.014899999999999899436 0.028149999999999578137 -0.0099000000000004015344" rpy="2.6040940641035082432e-31 1.570796326794896336 0" />
<geometry>
<mesh filename="package://optimo_description/meshes/plato/motor.stl"/>
</geometry>
<material name="motor_material">
<color rgba="0.90196078431372550543 0.90196078431372550543 0.90196078431372550543 1.0"/>
</material>
</visual>
<collision>
<origin xyz="-0.014899999999999899436 0.028149999999999578137 -0.0099000000000004015344" rpy="2.6040940641035082432e-31 1.570796326794896336 0" />
<geometry>
<mesh filename="package://optimo_description/meshes/plato/motor.stl"/>
</geometry>
</collision>
<visual>
<origin xyz="-3.4694469519536141888e-18 0 -0.019800000000000001626" rpy="-3.1415926535897926719 3.1762611116722443688e-16 3.141592653589793116" />
<geometry>
<mesh filename="package://optimo_description/meshes/plato/mcp_yaw_connect.stl"/>
</geometry>
<material name="mcp_yaw_connect_material">
<color rgba="0.90196078431372550543 0.90196078431372550543 0.90196078431372550543 1.0"/>
</material>
</visual>
<collision>
<origin xyz="-3.4694469519536141888e-18 0 -0.019800000000000001626" rpy="-3.1415926535897926719 3.1762611116722443688e-16 3.141592653589793116" />
<geometry>
<mesh filename="package://optimo_description/meshes/plato/mcp_yaw_connect.stl"/>
</geometry>
</collision>
<inertial>
<origin xyz="-0.0079504685553139359255 0.013983661603933878262 -0.010286902688940540579" rpy="0 0 0"/>
<mass value="0.12656081824380860379" />
<inertia ixx="3.5117165939881223459e-05" ixy="1.3052140141475956884e-05"  ixz="-1.9957519826351961518e-07" iyy="1.7537495218030094688e-05" iyz="-4.9180486622795326117e-07" izz="4.2451494821235971307e-05" />
</inertial>
</link>

<link name="mcp_pitch_2">
<visual>
<origin xyz="0 0 -6.9388939039072283776e-18" rpy="1.570796326794896558 1.570796326794896558 0" />
<geometry>
<mesh filename="package://optimo_description/meshes/plato/mcp_pitch_connect.stl"/>
</geometry>
<material name="mcp_pitch_connect_material">
<color rgba="0.90196078431372550543 0.90196078431372550543 0.90196078431372550543 1.0"/>
</material>
</visual>
<collision>
<origin xyz="0 0 -6.9388939039072283776e-18" rpy="1.570796326794896558 1.570796326794896558 0" />
<geometry>
<mesh filename="package://optimo_description/meshes/plato/mcp_pitch_connect.stl"/>
</geometry>
</collision>
<visual>
<origin xyz="0 1.7347234759768070944e-18 -0.016399999999999980566" rpy="-5.991802860914466036e-16 1.7451588453829230951e-16 -1.570796326794896558" />
<geometry>
<mesh filename="package://optimo_description/meshes/plato/motor.stl"/>
</geometry>
<material name="motor_material">
<color rgba="0.90196078431372550543 0.90196078431372550543 0.90196078431372550543 1.0"/>
</material>
</visual>
<collision>
<origin xyz="0 1.7347234759768070944e-18 -0.016399999999999980566" rpy="-5.991802860914466036e-16 1.7451588453829230951e-16 -1.570796326794896558" />
<geometry>
<mesh filename="package://optimo_description/meshes/plato/motor.stl"/>
</geometry>
</collision>
<visual>
<origin xyz="0.020000000000000017764 2.6020852139652106416e-18 -0.0050000000000000009714" rpy="1.570796326794896558 -1.570796326794896558 0" />
<geometry>
<mesh filename="package://optimo_description/meshes/plato/phlange.stl"/>
</geometry>
<material name="phlange_material">
<color rgba="0.90196078431372550543 0.90196078431372550543 0.90196078431372550543 1.0"/>
</material>
</visual>
<collision>
<origin xyz="0.020000000000000017764 2.6020852139652106416e-18 -0.0050000000000000009714" rpy="1.570796326794896558 -1.570796326794896558 0" />
<geometry>
<mesh filename="package://optimo_description/meshes/plato/phlange.stl"/>
</geometry>
</collision>
<inertial>
<origin xyz="0.0020817714488827595773 3.9659158286529116865e-10 -0.015795112278833196157" rpy="0 0 0"/>
<mass value="0.069114549940711839104" />
<inertia ixx="5.8883565545031163691e-06" ixy="-9.2074790702916195538e-09"  ixz="-1.1640174651111035441e-06" iyy="9.6829622072775829646e-06" iyz="-9.4322528370318213712e-14" izz="9.2871592762525291841e-06" />
</inertial>
</link>

<link name="pip_2">
<visual>
<origin xyz="0.02400024181276727564 -0.030174068124402667057 -0.072096228994410066493" rpy="-3.8455702303801045871e-17 1.570796326794896558 0" />
<geometry>
<mesh filename="package://optimo_description/meshes/plato/ft_sensor.stl"/>
</geometry>
<material name="ft_sensor_material">
<color rgba="0.90196078431372550543 0.90196078431372550543 0.90196078431372550543 1.0"/>
</material>
</visual>
<collision>
<origin xyz="0.02400024181276727564 -0.030174068124402667057 -0.072096228994410066493" rpy="-3.8455702303801045871e-17 1.570796326794896558 0" />
<geometry>
<mesh filename="package://optimo_description/meshes/plato/ft_sensor.stl"/>
</geometry>
</collision>
<visual>
<origin xyz="2.7755575615628913511e-17 0 -0.0023000000000000034306" rpy="1.570796326794896558 1.570796326794896558 0" />
<geometry>
<mesh filename="package://optimo_description/meshes/plato/pip_connect.stl"/>
</geometry>
<material name="pip_connect_material">
<color rgba="0.90196078431372550543 0.90196078431372550543 0.90196078431372550543 1.0"/>
</material>
</visual>
<collision>
<origin xyz="2.7755575615628913511e-17 0 -0.0023000000000000034306" rpy="1.570796326794896558 1.570796326794896558 0" />
<geometry>
<mesh filename="package://optimo_description/meshes/plato/pip_connect.stl"/>
</geometry>
</collision>
<visual>
<origin xyz="0.029600000000000403766 -2.6714741530042829254e-16 -0.0023000000000000624112" rpy="1.57079632679489678 -1.5707963267948885644 0" />
<geometry>
<mesh filename="package://optimo_description/meshes/plato/fingertip.stl"/>
</geometry>
<material name="fingertip_material">
<color rgba="0.90196078431372550543 0.90196078431372550543 0.90196078431372550543 1.0"/>
</material>
</visual>
<collision>
<origin xyz="0.029600000000000403766 -2.6714741530042829254e-16 -0.0023000000000000624112" rpy="1.57079632679489678 -1.5707963267948885644 0" />
<geometry>
<mesh filename="package://optimo_description/meshes/plato/fingertip.stl"/>
</geometry>
</collision>
<inertial>
<origin xyz="0.020839063326584646163 -0.00066661768468521931906 -0.0023008505382949469287" rpy="0 0 0"/>
<mass value="0.0080671501064400203546" />
<inertia ixx="2.1185571765449401416e-07" ixy="3.642624395971956964e-08"  ixz="-1.3233834119088076431e-10" iyy="1.2852102149793435045e-06" iyz="-3.1084190128866667407e-11" izz="1.3237276294093188092e-06" />
</inertial>
</link>

<joint name="f1_pip" type="revolute">
<origin xyz="0.047999999999999903855 -2.168404344971008868e-17 -0.0027000000000000148881" rpy="1.9765098088167343583e-16 -1.6884641832840973333e-16 1.1730272203076969313e-15" />
<parent link="mcp_pitch_2" />
<child link="pip_2" />
<axis xyz="0 0 1"/>
<limit effort="1" velocity="20" lower="-2.0943951023931952626" upper="2.0943951023931952626"/>
<joint_properties friction="0.0"/>
</joint>

<joint name="f1_mcp_pitch" type="revolute">
<origin xyz="-0.0049999999999998448463 0.028149999999999578137 -0.0099000000000004015344" rpy="-1.57079632679489678 5.4372706163721089482e-16 1.5707963267948890085" />
<parent link="mcp_yaw_2" />
<child link="mcp_pitch_2" />
<axis xyz="0 0 1"/>
<limit effort="1" velocity="20" lower="-1.570796326794896558" upper="1.570796326794896558"/>
<joint_properties friction="0.0"/>
</joint>

<joint name="f1_mcp_yaw" type="revolute">
<origin xyz="-0.03000000000000006134 0.10000000000000007494 0.0050000000000002889355" rpy="6.6160665693078649485e-16 1.3227777264680761451e-16 -3.164135620181711523e-15" />
<parent link="base" />
<child link="mcp_yaw_2" />
<axis xyz="0 0 1"/>
<limit effort="1" velocity="20" lower="-0.26179938779914940783" upper="0.52359877559829881566"/>
<joint_properties friction="0.0"/>
</joint>

<link name="mcp_yaw_3">
<visual>
<origin xyz="0 0 -0.0099000000000000060174" rpy="-3.141592653589793116 -1.7150506586720740103e-31 1.1995228953660710908e-31" />
<geometry>
<mesh filename="package://optimo_description/meshes/plato/motor.stl"/>
</geometry>
<material name="motor_material">
<color rgba="0.90196078431372550543 0.90196078431372550543 0.90196078431372550543 1.0"/>
</material>
</visual>
<collision>
<origin xyz="0 0 -0.0099000000000000060174" rpy="-3.141592653589793116 -1.7150506586720740103e-31 1.1995228953660710908e-31" />
<geometry>
<mesh filename="package://optimo_description/meshes/plato/motor.stl"/>
</geometry>
</collision>
<visual>
<origin xyz="-0.014900000000000393832 0.028149999999999994471 -0.0098999999999996313171" rpy="-1.1995228953648637846e-31 1.570796326794886788 0" />
<geometry>
<mesh filename="package://optimo_description/meshes/plato/motor.stl"/>
</geometry>
<material name="motor_material">
<color rgba="0.90196078431372550543 0.90196078431372550543 0.90196078431372550543 1.0"/>
</material>
</visual>
<collision>
<origin xyz="-0.014900000000000393832 0.028149999999999994471 -0.0098999999999996313171" rpy="-1.1995228953648637846e-31 1.570796326794886788 0" />
<geometry>
<mesh filename="package://optimo_description/meshes/plato/motor.stl"/>
</geometry>
</collision>
<visual>
<origin xyz="3.4694469519536141888e-18 -6.9388939039072283776e-18 -0.019800000000000012035" rpy="3.1415926535897815697 1.7150506586729743445e-31 -3.141592653589793116" />
<geometry>
<mesh filename="package://optimo_description/meshes/plato/mcp_yaw_connect.stl"/>
</geometry>
<material name="mcp_yaw_connect_material">
<color rgba="0.90196078431372550543 0.90196078431372550543 0.90196078431372550543 1.0"/>
</material>
</visual>
<collision>
<origin xyz="3.4694469519536141888e-18 -6.9388939039072283776e-18 -0.019800000000000012035" rpy="3.1415926535897815697 1.7150506586729743445e-31 -3.141592653589793116" />
<geometry>
<mesh filename="package://optimo_description/meshes/plato/mcp_yaw_connect.stl"/>
</geometry>
</collision>
<inertial>
<origin xyz="-0.0079504685553141822563 0.013983661603934082959 -0.010286902688940165879" rpy="0 0 0"/>
<mass value="0.12656081824380860379" />
<inertia ixx="3.511716593988192819e-05" ixy="1.3052140141476524396e-05"  ixz="-1.9957519826319414277e-07" iyy="1.7537495218030880735e-05" iyz="-4.9180486622856291313e-07" izz="4.2451494821237760241e-05" />
</inertial>
</link>

<link name="mcp_pitch_3">
<visual>
<origin xyz="0 0 -0.016399999999999900768" rpy="8.7506410863256617265e-31 -2.0142048418809762441e-32 -1.570796326794896558" />
<geometry>
<mesh filename="package://optimo_description/meshes/plato/motor.stl"/>
</geometry>
<material name="motor_material">
<color rgba="0.90196078431372550543 0.90196078431372550543 0.90196078431372550543 1.0"/>
</material>
</visual>
<collision>
<origin xyz="0 0 -0.016399999999999900768" rpy="8.7506410863256617265e-31 -2.0142048418809762441e-32 -1.570796326794896558" />
<geometry>
<mesh filename="package://optimo_description/meshes/plato/motor.stl"/>
</geometry>
</collision>
<visual>
<origin xyz="0.020000000000000087153 6.9388939039072283776e-17 -0.0050000000000000946465" rpy="1.570796326794896558 -1.570796326794896558 0" />
<geometry>
<mesh filename="package://optimo_description/meshes/plato/phlange.stl"/>
</geometry>
<material name="phlange_material">
<color rgba="0.90196078431372550543 0.90196078431372550543 0.90196078431372550543 1.0"/>
</material>
</visual>
<collision>
<origin xyz="0.020000000000000087153 6.9388939039072283776e-17 -0.0050000000000000946465" rpy="1.570796326794896558 -1.570796326794896558 0" />
<geometry>
<mesh filename="package://optimo_description/meshes/plato/phlange.stl"/>
</geometry>
</collision>
<visual>
<origin xyz="0 -6.9388939039072283776e-18 3.4694469519536141888e-18" rpy="1.570796326794896558 1.570796326794896558 0" />
<geometry>
<mesh filename="package://optimo_description/meshes/plato/mcp_pitch_connect.stl"/>
</geometry>
<material name="mcp_pitch_connect_material">
<color rgba="0.90196078431372550543 0.90196078431372550543 0.90196078431372550543 1.0"/>
</material>
</visual>
<collision>
<origin xyz="0 -6.9388939039072283776e-18 3.4694469519536141888e-18" rpy="1.570796326794896558 1.570796326794896558 0" />
<geometry>
<mesh filename="package://optimo_description/meshes/plato/mcp_pitch_connect.stl"/>
</geometry>
</collision>
<inertial>
<origin xyz="0.0020817714488827834297 3.9659158348997067772e-10 -0.015795112278833133707" rpy="0 0 0"/>
<mass value="0.069114549940711825227" />
<inertia ixx="5.8883565545031434741e-06" ixy="-9.2074790703028377773e-09"  ixz="-1.1640174651110965561e-06" iyy="9.6829622072777235721e-06" iyz="-9.4322543404407320417e-14" izz="9.2871592762527307779e-06" />
</inertial>
</link>

<link name="pip_3">
<visual>
<origin xyz="0.024000241812767539318 -0.030174068124402052965 -0.072096228994409178314" rpy="-1.2671078290112787989e-29 1.570796326794896336 0" />
<geometry>
<mesh filename="package://optimo_description/meshes/plato/ft_sensor.stl"/>
</geometry>
<material name="ft_sensor_material">
<color rgba="0.90196078431372550543 0.90196078431372550543 0.90196078431372550543 1.0"/>
</material>
</visual>
<collision>
<origin xyz="0.024000241812767539318 -0.030174068124402052965 -0.072096228994409178314" rpy="-1.2671078290112787989e-29 1.570796326794896336 0" />
<geometry>
<mesh filename="package://optimo_description/meshes/plato/ft_sensor.stl"/>
</geometry>
</collision>
<visual>
<origin xyz="0.029599999999999584976 -3.6776137690708310402e-16 -0.0022999999999998160805" rpy="1.57079632679489678 -1.570796326794896558 0" />
<geometry>
<mesh filename="package://optimo_description/meshes/plato/fingertip.stl"/>
</geometry>
<material name="fingertip_material">
<color rgba="0.90196078431372550543 0.90196078431372550543 0.90196078431372550543 1.0"/>
</material>
</visual>
<collision>
<origin xyz="0.029599999999999584976 -3.6776137690708310402e-16 -0.0022999999999998160805" rpy="1.57079632679489678 -1.570796326794896558 0" />
<geometry>
<mesh filename="package://optimo_description/meshes/plato/fingertip.stl"/>
</geometry>
</collision>
<visual>
<origin xyz="0 0 -0.0022999999999999930222" rpy="1.570796326794896558 1.570796326794896558 0" />
<geometry>
<mesh filename="package://optimo_description/meshes/plato/pip_connect.stl"/>
</geometry>
<material name="pip_connect_material">
<color rgba="0.90196078431372550543 0.90196078431372550543 0.90196078431372550543 1.0"/>
</material>
</visual>
<collision>
<origin xyz="0 0 -0.0022999999999999930222" rpy="1.570796326794896558 1.570796326794896558 0" />
<geometry>
<mesh filename="package://optimo_description/meshes/plato/pip_connect.stl"/>
</geometry>
</collision>
<inertial>
<origin xyz="0.020839063326584188196 -0.00066661768468528025122 -0.0023008505382948020793" rpy="0 0 0"/>
<mass value="0.0080671501064400203546" />
<inertia ixx="2.1185571765447654411e-07" ixy="3.6426243959718848339e-08"  ixz="-1.3233834119766679896e-10" iyy="1.2852102149792748948e-06" iyz="-3.1084190123954830156e-11" izz="1.3237276294092495642e-06" />
</inertial>
</link>

<joint name="f0_pip" type="revolute">
<origin xyz="0.048000000000001111222 5.5511151231257827021e-17 -0.0073000000000001119549" rpy="3.1415926535897651384 -1.1905645582292187618e-16 2.7750278304630428599e-15" />
<parent link="mcp_pitch_3" />
<child link="pip_3" />
<axis xyz="0 0 1"/>
<limit effort="1" velocity="20" lower="-2.0943951023931952626" upper="2.0943951023931952626"/>
<joint_properties friction="0.0"/>
</joint>

<joint name="f0_mcp_pitch" type="revolute">
<origin xyz="-0.00500000000000032363 0.02815000000000000141 -0.0098999999999996313171" rpy="3.141592653589793116 1.5707963267948927832 0" />
<parent link="mcp_yaw_3" />
<child link="mcp_pitch_3" />
<axis xyz="0 0 1"/>
<limit effort="1" velocity="20" lower="-1.570796326794896558" upper="0.52359877559829881566"/>
<joint_properties friction="0.0"/>
</joint>

<joint name="f0_mcp_roll" type="revolute">
<origin xyz="-0.030000000000000050931 0.065000000000000196509 -0.033000000000000168088" rpy="-1.57079632679489678 2.4059345662591521622e-15 -3.1415926535897917837" />
<parent link="base" />
<child link="mcp_yaw_3" />
<axis xyz="0 0 1"/>
<limit effort="1" velocity="20" lower="-1.0471975511965976313" upper="0.52359877559829881566"/>
<joint_properties friction="0.0"/>
</joint>


</robot>
