<?xml version="1.0"?>
<robot xmlns:xacro="http://www.ros.org/wiki/xacro">

    <link name="plato_base_link"></link>

    <joint name="plato_base_link_to_palm" type="fixed">
        <parent link="plato_base_link"/>
        <child link="palm_base" />
        <origin rpy="0.0 0 0" xyz="0 0 0"/>
    </joint>

    <link name="palm_base">
        <visual>
        <origin xyz="0 0 0" rpy="0 -0 0" />
        <geometry>
        <mesh filename="file://$(find plato_description)/meshes/plato/palm_base_visual.stl"/>
        </geometry>
        <material name="palm_base_material">
        <color rgba="0.90430433047923486356 0.90886394804751480248 0.9115997185884826548 1.0"/>
        </material>
        </visual>
        <collision>
        <origin xyz="0 0 0" rpy="0 -0 0" />
        <geometry>
        <mesh filename="file://$(find plato_description)/meshes/plato/palm_base_collision.stl"/>
        </geometry>
        </collision>
        <inertial>
        <origin xyz="0.072994256020995074152 0.00067586696183425168643 -0.0042612566810514640805" rpy="0 0 0"/>
        <mass value="0.19041183529585872791" />
        <inertia ixx="0.00014689194474371008873" ixy="-7.521003432555432779e-06"  ixz="3.8361860342483935105e-05" iyy="0.00043768569967403859067" iyz="2.4154367624475386874e-06" izz="0.00046084466088542274352" />
        </inertial>
    </link>
    
    <!-- Finger 1 -->
    <link name="plato_f1_proxbracket">
        <visual>
        <origin xyz="0 0 0" rpy="0 -0 0" />
        <geometry>
        <mesh filename="file://$(find plato_description)/meshes/plato/proxbracket_visual.stl"/>
        </geometry>
        <material name="proxbracket_material">
        <color rgba="0.29588156155479994336 0.31447294875599396402 0.33306433595718798468 1.0"/>
        </material>
        </visual>
        <collision>
        <origin xyz="0 0 0" rpy="0 -0 0" />
        <geometry>
        <mesh filename="file://$(find plato_description)/meshes/plato/proxbracket_collision.stl"/>
        </geometry>
        </collision>
        <inertial>
        <origin xyz="-0.0079504685553139810283 -0.013983661603934084694 -0.0095130973110596501324" rpy="0 0 0"/>
        <mass value="0.12656081824380857603" />
        <inertia ixx="3.5117165939881846875e-05" ixy="-1.3052140141476188971e-05"  ixz="1.9957519826333578256e-07" iyy="1.7537495218030348798e-05" iyz="-4.9180486622831070907e-07" izz="4.2451494821237238469e-05" />
        </inertial>
    </link>

    <link name="plato_f1_prox">
        <visual>
        <origin xyz="0 0 0" rpy="0 -0 0" />
        <geometry>
        <mesh filename="file://$(find plato_description)/meshes/plato/prox_visual.stl"/>
        </geometry>
        <material name="prox_material">
        <color rgba="0.34674225592475715896 0.3637734991268727347 0.38080474232898831044 1.0"/>
        </material>
        </visual>
        <collision>
        <origin xyz="0 0 0" rpy="0 -0 0" />
        <geometry>
        <mesh filename="file://$(find plato_description)/meshes/plato/prox_collision.stl"/>
        </geometry>
        </collision>
        <inertial>
        <origin xyz="0.0020628634950129870473 3.9571813644175597542e-10 -0.015800949225316978514" rpy="0 0 0"/>
        <mass value="0.069077199724865326336" />
        <inertia ixx="5.8838183215242009162e-06" ixy="-9.2074653187504296242e-09"  ixz="-1.1499102511779078509e-06" iyy="9.6333284963107829337e-06" iyz="-9.5358043888118201274e-14" izz="9.2423803001318981937e-06" />
        </inertial>
    </link>

    <link name="plato_f1_mid">
        <visual>
        <origin xyz="0 0 0" rpy="0 -0 0" />
        <geometry>
        <mesh filename="file://$(find plato_description)/meshes/plato/mid_visual.stl"/>
        </geometry>
        <material name="mid_material">
        <color rgba="0.64620900693609528709 0.65558443969472113277 0.66478059645223397389 1.0"/>
        </material>
        </visual>
        <collision>
        <origin xyz="0 0 0" rpy="0 -0 0" />
        <geometry>
        <mesh filename="file://$(find plato_description)/meshes/plato/mid_collision.stl"/>
        </geometry>
        </collision>
        <inertial>
        <origin xyz="0.02188265244158399056 -0.00092626544337760113607 -0.0023008125910619699368" rpy="0 0 0"/>
        <mass value="0.0084384550266508422112" />
        <inertia ixx="2.2607154456153991128e-07" ixy="8.6363020365647748704e-08"  ixz="-1.3958263749757479533e-10" iyy="1.4903406243236690009e-06" iyz="-2.9321372897392038018e-11" izz="1.5424304598462963454e-06" />
        </inertial>
    </link>

    <joint name="plato_f1_pip_pitch" type="revolute">
        <origin xyz="0.047999999999999293232 -9.7144514654701197287e-17 -0.0027000000000018120616" rpy="-2.1461177382147364842e-14 2.258685845680399537e-14 1.1702444568937959782e-14" />
        <parent link="plato_f1_prox" />
        <child link="plato_f1_mid" />
        <axis xyz="0 0 1"/>
        <limit effort="1" velocity="20" lower="-1.570796326794896558" upper="0.34906585039886589561"/>
        <joint_properties friction="0.0"/>
    </joint>

    <joint name="plato_f1_mcp_pitch" type="revolute">
        <origin xyz="-0.0050000000000000009714 -0.028150000000000004879 -0.0098999999999999921396" rpy="-4.3545121968198811335e-28 -1.5707963267948379382 0" />
        <parent link="plato_f1_proxbracket" />
        <child link="plato_f1_prox" />
        <axis xyz="0 0 1"/>
        <limit effort="1" velocity="20" lower="-1.570796326794896558" upper="0.52359877559829881566"/>
        <joint_properties friction="0.0"/>
    </joint>

    <joint name="plato_f1_mcp_roll" type="revolute">
        <origin xyz="0.15070000000000047247 0.029000000000000043104 -0.031000000000000055289" rpy="1.5707963267948970021 -4.0301095793892904738e-14 1.57079632679489678" />
        <parent link="palm_base" />
        <child link="plato_f1_proxbracket" />
        <axis xyz="0 0 1"/>
        <limit effort="1" velocity="20" lower="-0.52359877559829881566" upper="1.0471975511965976313"/>
        <joint_properties friction="0.0"/>
    </joint>


    <link name="plato_f1_ee_frame"/>
    <joint name="plato_f1_ee_joint" type="fixed">
        <origin xyz="0.05060 0.0 0.0" rpy="-1.5707 0.0 0.0"/>
        <parent link="plato_f1_mid"/>
        <child link="plato_f1_ee_frame"/>
    </joint>

    <!-- Finger 2 -->
    <link name="plato_f2_proxbracket">
        <visual>
        <origin xyz="0 0 0" rpy="0 -0 0" />
        <geometry>
        <mesh filename="file://$(find plato_description)/meshes/plato/proxbracket_2_visual.stl"/>
        </geometry>
        <material name="proxbracket_2_material">
        <color rgba="0.29588156155479994336 0.31447294875599396402 0.33306433595718798468 1.0"/>
        </material>
        </visual>
        <collision>
        <origin xyz="0 0 0" rpy="0 -0 0" />
        <geometry>
        <mesh filename="file://$(find plato_description)/meshes/plato/proxbracket_2_collision.stl"/>
        </geometry>
        </collision>
        <inertial>
        <origin xyz="-0.0079504685553140122534 0.013983661603934131532 -0.010286902688940285575" rpy="0 0 0"/>
        <mass value="0.12656081824380857603" />
        <inertia ixx="3.5117165939882111149e-05" ixy="1.3052140141476243181e-05"  ixz="-1.9957519826321783322e-07" iyy="1.7537495218030467383e-05" iyz="-4.9180486622837381303e-07" izz="4.2451494821237563729e-05" />
        </inertial>
    </link>

    <link name="plato_f2_prox">
        <visual>
        <origin xyz="0 0 0" rpy="0 -0 0" />
        <geometry>
        <mesh filename="file://$(find plato_description)/meshes/plato/prox_2_visual.stl"/>
        </geometry>
        <material name="prox_2_material">
        <color rgba="0.34674225592475710345 0.36377349912687267919 0.38080474232898825493 1.0"/>
        </material>
        </visual>
        <collision>
        <origin xyz="0 0 0" rpy="0 -0 0" />
        <geometry>
        <mesh filename="file://$(find plato_description)/meshes/plato/prox_2_collision.stl"/>
        </geometry>
        </collision>
        <inertial>
        <origin xyz="0.0020628634950129809758 3.9571813821659491937e-10 -0.015800949225316756469" rpy="0 0 0"/>
        <mass value="0.069077199724865326336" />
        <inertia ixx="5.8838183215241543294e-06" ixy="-9.2074653187181364931e-09"  ixz="-1.1499102511777331503e-06" iyy="9.6333284963107575227e-06" iyz="-9.5358150885037654931e-14" izz="9.2423803001321489154e-06" />
        </inertial>
    </link>

    <link name="plato_f2_mid">
        <visual>
        <origin xyz="0 0 0" rpy="0 -0 0" />
        <geometry>
        <mesh filename="file://$(find plato_description)/meshes/plato/mid_2_visual.stl"/>
        </geometry>
        <material name="mid_2_material">
        <color rgba="0.64620900693609528709 0.65558443969472113277 0.66478059645223397389 1.0"/>
        </material>
        </visual>
        <collision>
        <origin xyz="0 0 0" rpy="0 -0 0" />
        <geometry>
        <mesh filename="file://$(find plato_description)/meshes/plato/mid_2_collision.stl"/>
        </geometry>
        </collision>
        <inertial>
        <origin xyz="0.021882652441584021785 0.0009262654433775824878 -0.0020991874089382363266" rpy="0 0 0"/>
        <mass value="0.0084384550266508422112" />
        <inertia ixx="2.2607154456154081125e-07" ixy="-8.6363020365652076513e-08"  ixz="1.3958263751594820865e-10" iyy="1.4903406243236685774e-06" iyz="-2.9321372899717701546e-11" izz="1.5424304598462938043e-06" />
        </inertial>
    </link>

    <joint name="plato_f2_pip_pitch" type="revolute">
        <origin xyz="0.047999999999998960165 -1.4627242559545061695e-16 -0.0029000000000008394063" rpy="8.6736173798921644372e-17 2.6809573080062448739e-14 -5.1904703123014745533e-17" />
        <parent link="plato_f2_prox" />
        <child link="plato_f2_mid" />
        <axis xyz="0 0 1"/>
        <limit effort="1" velocity="20" lower="-1.570796326794896558" upper="0.34906585039886589561"/>
        <joint_properties friction="0.0"/>
    </joint>

    <joint name="plato_f2_mcp_pitch" type="revolute">
        <origin xyz="-0.0049999999999999801548 0.028150000000000091616 -0.0098999999999997475436" rpy="-1.5707963267949098807 1.0921682003593975385e-14 1.5707963267949234254" />
        <parent link="plato_f2_proxbracket" />
        <child link="plato_f2_prox" />
        <axis xyz="0 0 1"/>
        <limit effort="1" velocity="20" lower="-1.570796326794896558" upper="1.570796326794896558"/>
        <joint_properties friction="0.0"/>
    </joint>

    <joint name="plato_f2_mcp_yaw" type="revolute">
        <origin xyz="0.14970000000000047158 0.029000000000000046574 -0.01000000000000005225" rpy="-3.141592653589793116 1.0230539864584981437e-29 1.570796326794896558" />
        <parent link="palm_base" />
        <child link="plato_f2_proxbracket" />
        <axis xyz="0 0 1"/>
        <limit effort="1" velocity="20" lower="-0.26179938779914940783" upper="0.26179938779914940783"/>
        <joint_properties friction="0.0"/>
    </joint>

    <link name="plato_f2_ee_frame"/>
    <joint name="plato_f2_ee_joint" type="fixed">
        <origin xyz="0.05060 0.0 0.0" rpy="-1.5707 0.0 0.0"/>
        <parent link="plato_f2_mid"/>
        <child link="plato_f2_ee_frame"/>
    </joint>


   <!-- Finger 3 -->
   <link name="plato_f3_proxbracket">
        <visual>
        <origin xyz="0 0 0" rpy="0 -0 0" />
        <geometry>
        <mesh filename="file://$(find plato_description)/meshes/plato/proxbracket_3_visual.stl"/>
        </geometry>
        <material name="proxbracket_3_material">
        <color rgba="0.29588156155479994336 0.31447294875599396402 0.33306433595718798468 1.0"/>
        </material>
        </visual>
        <collision>
        <origin xyz="0 0 0" rpy="0 -0 0" />
        <geometry>
        <mesh filename="file://$(find plato_description)/meshes/plato/proxbracket_3_collision.stl"/>
        </geometry>
        </collision>
        <inertial>
        <origin xyz="-0.0079504685553140694992 0.013983661603934159287 -0.010286902688940467721" rpy="0 0 0"/>
        <mass value="0.12656081824380857603" />
        <inertia ixx="3.5117165939882538054e-05" ixy="1.3052140141476453245e-05"  ixz="-1.9957519826336836686e-07" iyy="1.7537495218030582579e-05" iyz="-4.9180486622808476304e-07" izz="4.2451494821237523072e-05" />
        </inertial>
    </link>

    <link name="plato_f3_prox">
        <visual>
        <origin xyz="0 0 0" rpy="0 -0 0" />
        <geometry>
        <mesh filename="file://$(find plato_description)/meshes/plato/prox_3_visual.stl"/>
        </geometry>
        <material name="prox_3_material">
        <color rgba="0.34674225592475710345 0.36377349912687267919 0.38080474232898825493 1.0"/>
        </material>
        </visual>
        <collision>
        <origin xyz="0 0 0" rpy="0 -0 0" />
        <geometry>
        <mesh filename="file://$(find plato_description)/meshes/plato/prox_3_collision.stl"/>
        </geometry>
        </collision>
        <inertial>
        <origin xyz="0.0020628634950130113335 3.9571814151545830726e-10 -0.015800949225316409524" rpy="0 0 0"/>
        <mass value="0.069077199724865326336" />
        <inertia ixx="5.8838183215244804371e-06" ixy="-9.2074653187602681104e-09"  ixz="-1.1499102511776793637e-06" iyy="9.6333284963110302673e-06" iyz="-9.5358075211394208756e-14" izz="9.2423803001327079572e-06" />
        </inertial>
    </link>

    <link name="plato_f3_mid">
        <visual>
        <origin xyz="0 0 0" rpy="0 -0 0" />
        <geometry>
        <mesh filename="file://$(find plato_description)/meshes/plato/mid_3_visual.stl"/>
        </geometry>
        <material name="mid_3_material">
        <color rgba="0.64620900693609528709 0.6555844396947212438 0.66478059645223397389 1.0"/>
        </material>
        </visual>
        <collision>
        <origin xyz="0 0 0" rpy="0 -0 0" />
        <geometry>
        <mesh filename="file://$(find plato_description)/meshes/plato/mid_3_collision.stl"/>
        </geometry>
        </collision>
        <inertial>
        <origin xyz="0.021882652441584111991 0.00092626544337756557424 -0.0020991874089382198468" rpy="0 0 0"/>
        <mass value="0.0084384550266508422112" />
        <inertia ixx="2.2607154456154528464e-07" ixy="-8.6363020365655411705e-08"  ixz="1.3958263751436258096e-10" iyy="1.4903406243236912356e-06" iyz="-2.9321372899647365345e-11" izz="1.5424304598463122272e-06" />
        </inertial>
    </link>

    <joint name="plato_f3_pip_pitch" type="revolute">
        <origin xyz="0.048000000000000542233 -4.0156137963431870475e-17 -0.0029000000000002287837" rpy="1.0555934094656064912e-14 1.1602401833798466844e-14 1.6653345369355321631e-16" />
        <parent link="plato_f3_prox" />
        <child link="plato_f3_mid" />
        <axis xyz="0 0 1"/>
        <limit effort="1" velocity="20" lower="-1.570796326794896558" upper="0.34906585039886589561"/>
        <joint_properties friction="0.0"/>
    </joint>

    <joint name="plato_f3_mcp_pitch" type="revolute">
        <origin xyz="-0.0049999999999998274991 0.028150000000000174882 -0.0099000000000001205092" rpy="-1.5707963267949085484 6.1550351739900040327e-15 1.5707963267948936714" />
        <parent link="plato_f3_proxbracket" />
        <child link="plato_f3_prox" />
        <axis xyz="0 0 1"/>
        <limit effort="1" velocity="20" lower="-1.570796326794896558" upper="1.570796326794896558"/>
        <joint_properties friction="0.0"/>
    </joint>

    <joint name="plato_f3_mcp_yaw" type="revolute">
        <origin xyz="0.14970000000000047158 -0.029000000000000088207 -0.01000000000000005225" rpy="3.1415926535897891192 -1.7461186382788093093e-14 1.5707963267949038855" />
        <parent link="palm_base" />
        <child link="plato_f3_proxbracket" />
        <axis xyz="0 0 1"/>
        <limit effort="1" velocity="20" lower="-0.26179938779914940783" upper="0.26179938779914940783"/>
        <joint_properties friction="0.0"/>
    </joint>

    <link name="plato_f3_ee_frame"/>
    <joint name="plato_f3_ee_joint" type="fixed">
        <origin xyz="0.05060 0.0 0.0" rpy="-1.5707 0.0 0.0"/>
        <parent link="plato_f3_mid"/>
        <child link="plato_f3_ee_frame"/>
    </joint>

</robot>
